-------------------- Log Start | Mon Apr 15 04:37:01 2024 --------------------
data_path: /home/daniel/printer_data
is_default_data_path: False
config_file: /home/daniel/printer_data/config/moonraker.conf
startup_warnings: []
verbose: False
debug: False
asyncio_debug: False
is_backup_config: False
is_python_package: False
instance_uuid: b58008b63adb40a8a31f7dfdb480fcc5
unix_socket_path: /home/daniel/printer_data/comms/moonraker.sock
software_version: v0.8.0-311-g65a8271
git_branch: master
git_remote: origin
git_repo_url: https://github.com/Arksine/moonraker.git
modified_files: []
unofficial_components: []
log_file: /home/daniel/printer_data/logs/moonraker.log
python_version: 3.10.12 (main, Nov 20 2023, 15:14:05) [GCC 11.4.0]
launch_args: /home/daniel/moonraker-env/bin/python /home/daniel/moonraker/moonraker/moonraker.py -d /home/daniel/printer_data
msgspec_enabled: False
uvloop_enabled: False

#################### Moonraker Configuration ####################

[server]
host = 0.0.0.0
port = 7125
klippy_uds_address = /home/daniel/printer_data/comms/klippy.sock

[authorization]
trusted_clients = 
	10.0.0.0/8
	127.0.0.0/8
	169.254.0.0/16
	172.16.0.0/12
	192.168.0.0/16
	FE80::/10
	::1/128
cors_domains = 
	*.lan
	*.local
	*://localhost
	*://localhost:*
	*://my.mainsail.xyz
	*://app.fluidd.xyz

[octoprint_compat]

[file_manager]
enable_object_processing = True

[power printer_plug]
type = tplink_smartplug
address = 192.168.0.83

[history]

[update_manager]
channel = dev
refresh_interval = 168

[update_manager mainsail-config]
type = git_repo
primary_branch = master
path = ~/mainsail-config
origin = https://github.com/mainsail-crew/mainsail-config.git
managed_services = klipper

[update_manager mainsail]
type = web
channel = stable
repo = mainsail-crew/mainsail
path = ~/mainsail

[update_manager Klipper-Adaptive-Meshing-Purging]
type = git_repo
channel = dev
path = ~/Klipper-Adaptive-Meshing-Purging
origin = https://github.com/kyleisah/Klipper-Adaptive-Meshing-Purging.git
managed_services = klipper
primary_branch = main

[update_manager klipper-backup]
type = git_repo
path = ~/klipper-backup
origin = https://github.com/Staubgeborener/klipper-backup.git
managed_services = moonraker
primary_branch = main

[update_manager crowsnest]
type = git_repo
path = ~/crowsnest
origin = https://github.com/mainsail-crew/crowsnest.git
managed_services = crowsnest
install_script = tools/pkglist.sh

#################################################################
All Configuration Files:
/home/daniel/printer_data/config/moonraker.conf
#################################################################

Database Versions: pylmdb = 1.4.1, lmdb = (0, 9, 29)
Unsafe Shutdown Count: 2

System Info:

***python***
  version: (3, 10, 12, 'final', 0)
  version_string: 3.10.12 (main, Nov 20 2023, 15:14:05) [GCC 11.4.0]

***cpu_info***
  cpu_count: 4
  bits: 64bit
  processor: x86_64
  cpu_desc: Intel(R) Core(TM) i5-5200U CPU @ 2.20GHz
  serial_number: 
  hardware_desc: 
  model: 
  total_memory: 12115920
  memory_units: kB

***sd_info***

***distribution***
  name: Ubuntu 22.04.4 LTS
  id: ubuntu
  version: 22.04
  version_parts: {'major': '22', 'minor': '04', 'build_number': ''}
  like: debian
  codename: jammy
  release_info: {}

***virtualization***
  virt_type: none
  virt_identifier: none

***network***

***canbus***

***Allowed Services***
  klipper_mcu
  webcamd
  MoonCord
  KlipperScreen
  moonraker-telegram-bot
  moonraker-obico
  sonar
  crowsnest
  octoeverywhere
  ratos-configurator
Module libcamera unavailble, import failed

Systemd unit moonraker.service:
unit_name: moonraker.service
is_default: True
manager: systemd
Properties:
**Requires=['system.slice', '-.mount', 'sysinit.target', 'network-online.target']
**After=['-.mount', 'systemd-journald.socket', 'network-online.target', 'sysinit.target', 'basic.target', 'system.slice']
**SupplementaryGroups=['moonraker-admin']
**EnvironmentFiles=/home/daniel/printer_data/systemd/moonraker.env
**ExecStart=/home/daniel/moonraker-env/bin/python $MOONRAKER_ARGS
**WorkingDirectory=/home/daniel/moonraker
**FragmentPath=/etc/systemd/system/moonraker.service
**Description=API Server for Klipper SV1
**User=daniel

Systemd unit klipper.service:
unit_name: klipper.service
is_default: True
manager: systemd
Properties:
**Requires=['system.slice', 'sysinit.target', '-.mount']
**After=['network-online.target', 'systemd-journald.socket', 'basic.target', 'system.slice', 'sysinit.target', '-.mount']
**SupplementaryGroups=[]
**EnvironmentFiles=/home/daniel/printer_data/systemd/klipper.env
**ExecStart=/home/daniel/klippy-env/bin/python $KLIPPER_ARGS
**WorkingDirectory=/home/daniel/klipper
**FragmentPath=/etc/systemd/system/klipper.service
**Description=Klipper 3D Printer Firmware SV1
**User=daniel
Git Repo moonraker: No warnings detected
Git Repo klipper: No warnings detected
Git Repo mainsail-config: No warnings detected
Git Repo Klipper-Adaptive-Meshing-Purging: No warnings detected
Git Repo klipper-backup: No warnings detected
Git Repo crowsnest: No warnings detected
Klipper Version: v0.12.0-111-g4f00f219
2024-04-15 00:20:20,274 [proc_stats.py:_watchdog_callback()] - EVENT LOOP BLOCKED: 3184.13 seconds, total blocked count: 122
2024-04-15 00:30:03,414 [proc_stats.py:log_last_stats()] - 
System Time: 1713151166.300629, Usage: 0.4%, Memory: 26344 kB
System Time: 1713151205.509481, Usage: 0.46%, Memory: 26308 kB
System Time: 1713151244.150433, Usage: 0.37%, Memory: 25328 kB
System Time: 1713151270.983412, Usage: 0.53%, Memory: 25328 kB
System Time: 1713151465.871197, Usage: 0.31%, Memory: 23556 kB
2024-04-15 00:44:16,331 [ioloop.py:_run_callback()] - Exception in callback functools.partial(<function _HTTPConnection.__init__.<locals>.<lambda> at 0x7f9b64170af0>, <Task finished name='Task-26995408' coro=<_HTTPConnection.run() done, defined at /home/daniel/moonraker-env/lib/python3.10/site-packages/tornado/simple_httpclient.py:290> exception=gaierror(-3, 'Temporary failure in name resolution')>)
Traceback (most recent call last):
  File "/home/daniel/moonraker-env/lib/python3.10/site-packages/tornado/ioloop.py", line 750, in _run_callback
    ret = callback()
  File "/home/daniel/moonraker-env/lib/python3.10/site-packages/tornado/simple_httpclient.py", line 287, in <lambda>
    gen.convert_yielded(self.run()), lambda f: f.result()
  File "/home/daniel/moonraker-env/lib/python3.10/site-packages/tornado/simple_httpclient.py", line 340, in run
    stream = await self.tcp_client.connect(
  File "/home/daniel/moonraker-env/lib/python3.10/site-packages/tornado/tcpclient.py", line 269, in connect
    addrinfo = await self.resolver.resolve(host, port, af)
  File "/home/daniel/moonraker-env/lib/python3.10/site-packages/tornado/netutil.py", line 433, in resolve
    for fam, _, _, _, address in await asyncio.get_running_loop().getaddrinfo(
  File "/usr/lib/python3.10/asyncio/base_events.py", line 863, in getaddrinfo
    return await self.run_in_executor(
  File "/usr/lib/python3.10/concurrent/futures/thread.py", line 58, in run
    result = self.fn(*self.args, **self.kwargs)
  File "/usr/lib/python3.10/socket.py", line 955, in getaddrinfo
    for res in _socket.getaddrinfo(host, port, family, type, proto, flags):
socket.gaierror: [Errno -3] Temporary failure in name resolution
2024-04-15 01:44:40,120 [proc_stats.py:_watchdog_callback()] - EVENT LOOP BLOCKED: 5093.2 seconds, total blocked count: 123
2024-04-15 01:47:46,237 [proc_stats.py:log_last_stats()] - 
System Time: 1713151205.509481, Usage: 0.46%, Memory: 26308 kB
System Time: 1713151244.150433, Usage: 0.37%, Memory: 25328 kB
System Time: 1713151270.983412, Usage: 0.53%, Memory: 25328 kB
System Time: 1713151465.871197, Usage: 0.31%, Memory: 23556 kB
System Time: 1713159751.401300, Usage: 0.22%, Memory: 23044 kB
2024-04-15 02:12:44,680 [proc_stats.py:_watchdog_callback()] - EVENT LOOP BLOCKED: 1645.34 seconds, total blocked count: 124
2024-04-15 02:21:04,706 [proc_stats.py:log_last_stats()] - 
System Time: 1713151205.509481, Usage: 0.46%, Memory: 26308 kB
System Time: 1713151244.150433, Usage: 0.37%, Memory: 25328 kB
System Time: 1713151270.983412, Usage: 0.53%, Memory: 25328 kB
System Time: 1713151465.871197, Usage: 0.31%, Memory: 23556 kB
System Time: 1713159751.401300, Usage: 0.22%, Memory: 23044 kB
2024-04-15 02:46:59,009 [concurrent.py:future_set_exception_unless_cancelled()] - Exception after Future was cancelled
tornado.simple_httpclient.HTTPTimeoutError: Timeout while connecting
2024-04-15 02:54:15,078 [ioloop.py:_run_callback()] - Exception in callback functools.partial(<function _HTTPConnection.__init__.<locals>.<lambda> at 0x7f9b64170700>, <Task finished name='Task-26995485' coro=<_HTTPConnection.run() done, defined at /home/daniel/moonraker-env/lib/python3.10/site-packages/tornado/simple_httpclient.py:290> exception=gaierror(-3, 'Temporary failure in name resolution')>)
Traceback (most recent call last):
  File "/home/daniel/moonraker-env/lib/python3.10/site-packages/tornado/ioloop.py", line 750, in _run_callback
    ret = callback()
  File "/home/daniel/moonraker-env/lib/python3.10/site-packages/tornado/simple_httpclient.py", line 287, in <lambda>
    gen.convert_yielded(self.run()), lambda f: f.result()
  File "/home/daniel/moonraker-env/lib/python3.10/site-packages/tornado/simple_httpclient.py", line 340, in run
    stream = await self.tcp_client.connect(
  File "/home/daniel/moonraker-env/lib/python3.10/site-packages/tornado/tcpclient.py", line 269, in connect
    addrinfo = await self.resolver.resolve(host, port, af)
  File "/home/daniel/moonraker-env/lib/python3.10/site-packages/tornado/netutil.py", line 433, in resolve
    for fam, _, _, _, address in await asyncio.get_running_loop().getaddrinfo(
  File "/usr/lib/python3.10/asyncio/base_events.py", line 863, in getaddrinfo
    return await self.run_in_executor(
  File "/usr/lib/python3.10/concurrent/futures/thread.py", line 58, in run
    result = self.fn(*self.args, **self.kwargs)
  File "/usr/lib/python3.10/socket.py", line 955, in getaddrinfo
    for res in _socket.getaddrinfo(host, port, family, type, proto, flags):
socket.gaierror: [Errno -3] Temporary failure in name resolution
2024-04-15 03:20:13,003 [proc_stats.py:_watchdog_callback()] - EVENT LOOP BLOCKED: 4089.54 seconds, total blocked count: 125
2024-04-15 03:27:51,165 [proc_stats.py:log_last_stats()] - 
System Time: 1713151205.509481, Usage: 0.46%, Memory: 26308 kB
System Time: 1713151244.150433, Usage: 0.37%, Memory: 25328 kB
System Time: 1713151270.983412, Usage: 0.53%, Memory: 25328 kB
System Time: 1713151465.871197, Usage: 0.31%, Memory: 23556 kB
System Time: 1713159751.401300, Usage: 0.22%, Memory: 23044 kB
2024-04-15 03:59:10,897 [proc_stats.py:_watchdog_callback()] - EVENT LOOP BLOCKED: 2333.16 seconds, total blocked count: 126
2024-04-15 04:06:08,207 [proc_stats.py:log_last_stats()] - 
System Time: 1713151244.150433, Usage: 0.37%, Memory: 25328 kB
System Time: 1713151270.983412, Usage: 0.53%, Memory: 25328 kB
System Time: 1713151465.871197, Usage: 0.31%, Memory: 23556 kB
System Time: 1713159751.401300, Usage: 0.22%, Memory: 23044 kB
System Time: 1713166481.745141, Usage: 0.21%, Memory: 24628 kB
2024-04-15 04:56:52,035 [proc_stats.py:_watchdog_callback()] - EVENT LOOP BLOCKED: 3469.17 seconds, total blocked count: 127
2024-04-15 05:01:12,416 [proc_stats.py:log_last_stats()] - 
System Time: 1713151244.150433, Usage: 0.37%, Memory: 25328 kB
System Time: 1713151270.983412, Usage: 0.53%, Memory: 25328 kB
System Time: 1713151465.871197, Usage: 0.31%, Memory: 23556 kB
System Time: 1713159751.401300, Usage: 0.22%, Memory: 23044 kB
System Time: 1713166481.745141, Usage: 0.21%, Memory: 24628 kB
2024-04-15 05:16:43,341 [concurrent.py:future_set_exception_unless_cancelled()] - Exception after Future was cancelled
tornado.simple_httpclient.HTTPTimeoutError: Timeout while connecting
2024-04-15 05:22:27,655 [ioloop.py:_run_callback()] - Exception in callback functools.partial(<function _HTTPConnection.__init__.<locals>.<lambda> at 0x7f9b64170b80>, <Task finished name='Task-26995580' coro=<_HTTPConnection.run() done, defined at /home/daniel/moonraker-env/lib/python3.10/site-packages/tornado/simple_httpclient.py:290> exception=gaierror(-3, 'Temporary failure in name resolution')>)
Traceback (most recent call last):
  File "/home/daniel/moonraker-env/lib/python3.10/site-packages/tornado/ioloop.py", line 750, in _run_callback
    ret = callback()
  File "/home/daniel/moonraker-env/lib/python3.10/site-packages/tornado/simple_httpclient.py", line 287, in <lambda>
    gen.convert_yielded(self.run()), lambda f: f.result()
  File "/home/daniel/moonraker-env/lib/python3.10/site-packages/tornado/simple_httpclient.py", line 340, in run
    stream = await self.tcp_client.connect(
  File "/home/daniel/moonraker-env/lib/python3.10/site-packages/tornado/tcpclient.py", line 269, in connect
    addrinfo = await self.resolver.resolve(host, port, af)
  File "/home/daniel/moonraker-env/lib/python3.10/site-packages/tornado/netutil.py", line 433, in resolve
    for fam, _, _, _, address in await asyncio.get_running_loop().getaddrinfo(
  File "/usr/lib/python3.10/asyncio/base_events.py", line 863, in getaddrinfo
    return await self.run_in_executor(
  File "/usr/lib/python3.10/concurrent/futures/thread.py", line 58, in run
    result = self.fn(*self.args, **self.kwargs)
  File "/usr/lib/python3.10/socket.py", line 955, in getaddrinfo
    for res in _socket.getaddrinfo(host, port, family, type, proto, flags):
socket.gaierror: [Errno -3] Temporary failure in name resolution
2024-04-15 05:49:06,401 [proc_stats.py:_watchdog_callback()] - EVENT LOOP BLOCKED: 3128.86 seconds, total blocked count: 128
2024-04-15 05:54:39,341 [proc_stats.py:log_last_stats()] - 
System Time: 1713151270.983412, Usage: 0.53%, Memory: 25328 kB
System Time: 1713151465.871197, Usage: 0.31%, Memory: 23556 kB
System Time: 1713159751.401300, Usage: 0.22%, Memory: 23044 kB
System Time: 1713166481.745141, Usage: 0.21%, Memory: 24628 kB
System Time: 1713173027.270582, Usage: 0.21%, Memory: 22792 kB
2024-04-15 06:37:57,473 [proc_stats.py:_watchdog_callback()] - EVENT LOOP BLOCKED: 2909.35 seconds, total blocked count: 129
2024-04-15 06:47:39,263 [proc_stats.py:log_last_stats()] - 
System Time: 1713151270.983412, Usage: 0.53%, Memory: 25328 kB
System Time: 1713151465.871197, Usage: 0.31%, Memory: 23556 kB
System Time: 1713159751.401300, Usage: 0.22%, Memory: 23044 kB
System Time: 1713166481.745141, Usage: 0.21%, Memory: 24628 kB
System Time: 1713173027.270582, Usage: 0.21%, Memory: 22792 kB
2024-04-15 07:14:44,479 [proc_stats.py:_watchdog_callback()] - EVENT LOOP BLOCKED: 2231.79 seconds, total blocked count: 130
2024-04-15 07:18:53,012 [proc_stats.py:log_last_stats()] - 
System Time: 1713151465.871197, Usage: 0.31%, Memory: 23556 kB
System Time: 1713159751.401300, Usage: 0.22%, Memory: 23044 kB
System Time: 1713166481.745141, Usage: 0.21%, Memory: 24628 kB
System Time: 1713173027.270582, Usage: 0.21%, Memory: 22792 kB
System Time: 1713178853.299887, Usage: 0.23%, Memory: 22816 kB
2024-04-15 07:28:15,678 [concurrent.py:future_set_exception_unless_cancelled()] - Exception after Future was cancelled
tornado.simple_httpclient.HTTPTimeoutError: Timeout while connecting
2024-04-15 07:37:30,013 [ioloop.py:_run_callback()] - Exception in callback functools.partial(<function _HTTPConnection.__init__.<locals>.<lambda> at 0x7f9b659b05e0>, <Task finished name='Task-26995651' coro=<_HTTPConnection.run() done, defined at /home/daniel/moonraker-env/lib/python3.10/site-packages/tornado/simple_httpclient.py:290> exception=gaierror(-3, 'Temporary failure in name resolution')>)
Traceback (most recent call last):
  File "/home/daniel/moonraker-env/lib/python3.10/site-packages/tornado/ioloop.py", line 750, in _run_callback
    ret = callback()
  File "/home/daniel/moonraker-env/lib/python3.10/site-packages/tornado/simple_httpclient.py", line 287, in <lambda>
    gen.convert_yielded(self.run()), lambda f: f.result()
  File "/home/daniel/moonraker-env/lib/python3.10/site-packages/tornado/simple_httpclient.py", line 340, in run
    stream = await self.tcp_client.connect(
  File "/home/daniel/moonraker-env/lib/python3.10/site-packages/tornado/tcpclient.py", line 269, in connect
    addrinfo = await self.resolver.resolve(host, port, af)
  File "/home/daniel/moonraker-env/lib/python3.10/site-packages/tornado/netutil.py", line 433, in resolve
    for fam, _, _, _, address in await asyncio.get_running_loop().getaddrinfo(
  File "/usr/lib/python3.10/asyncio/base_events.py", line 863, in getaddrinfo
    return await self.run_in_executor(
  File "/usr/lib/python3.10/concurrent/futures/thread.py", line 58, in run
    result = self.fn(*self.args, **self.kwargs)
  File "/usr/lib/python3.10/socket.py", line 955, in getaddrinfo
    for res in _socket.getaddrinfo(host, port, family, type, proto, flags):
socket.gaierror: [Errno -3] Temporary failure in name resolution
2024-04-15 07:57:06,277 [proc_stats.py:_watchdog_callback()] - EVENT LOOP BLOCKED: 2545.08 seconds, total blocked count: 131
2024-04-15 08:01:00,205 [proc_stats.py:log_last_stats()] - 
System Time: 1713151465.871197, Usage: 0.31%, Memory: 23556 kB
System Time: 1713159751.401300, Usage: 0.22%, Memory: 23044 kB
System Time: 1713166481.745141, Usage: 0.21%, Memory: 24628 kB
System Time: 1713173027.270582, Usage: 0.21%, Memory: 22792 kB
System Time: 1713178853.299887, Usage: 0.23%, Memory: 22816 kB
2024-04-15 08:20:13,296 [proc_stats.py:_watchdog_callback()] - EVENT LOOP BLOCKED: 1377.04 seconds, total blocked count: 132
2024-04-15 08:25:20,071 [proc_stats.py:log_last_stats()] - 
System Time: 1713151465.871197, Usage: 0.31%, Memory: 23556 kB
System Time: 1713159751.401300, Usage: 0.22%, Memory: 23044 kB
System Time: 1713166481.745141, Usage: 0.21%, Memory: 24628 kB
System Time: 1713173027.270582, Usage: 0.21%, Memory: 22792 kB
System Time: 1713178853.299887, Usage: 0.23%, Memory: 22816 kB
2024-04-15 08:46:41,781 [proc_stats.py:_watchdog_callback()] - EVENT LOOP BLOCKED: 1592.98 seconds, total blocked count: 133
2024-04-15 08:51:08,742 [proc_stats.py:log_last_stats()] - 
System Time: 1713151465.871197, Usage: 0.31%, Memory: 23556 kB
System Time: 1713159751.401300, Usage: 0.22%, Memory: 23044 kB
System Time: 1713166481.745141, Usage: 0.21%, Memory: 24628 kB
System Time: 1713173027.270582, Usage: 0.21%, Memory: 22792 kB
System Time: 1713178853.299887, Usage: 0.23%, Memory: 22816 kB
2024-04-15 08:58:57,498 [concurrent.py:future_set_exception_unless_cancelled()] - Exception after Future was cancelled
tornado.simple_httpclient.HTTPTimeoutError: Timeout while connecting
2024-04-15 09:06:39,585 [announcements.py:_fetch_moonlight()] - Failed to update subscription 'klipper': 
2024-04-15 09:10:12,259 [ioloop.py:_run_callback()] - Exception in callback functools.partial(<function _HTTPConnection.__init__.<locals>.<lambda> at 0x7f9b641705e0>, <Task finished name='Task-26995713' coro=<_HTTPConnection.run() done, defined at /home/daniel/moonraker-env/lib/python3.10/site-packages/tornado/simple_httpclient.py:290> exception=gaierror(-3, 'Temporary failure in name resolution')>)
Traceback (most recent call last):
  File "/home/daniel/moonraker-env/lib/python3.10/site-packages/tornado/ioloop.py", line 750, in _run_callback
    ret = callback()
  File "/home/daniel/moonraker-env/lib/python3.10/site-packages/tornado/simple_httpclient.py", line 287, in <lambda>
    gen.convert_yielded(self.run()), lambda f: f.result()
  File "/home/daniel/moonraker-env/lib/python3.10/site-packages/tornado/simple_httpclient.py", line 340, in run
    stream = await self.tcp_client.connect(
  File "/home/daniel/moonraker-env/lib/python3.10/site-packages/tornado/tcpclient.py", line 269, in connect
    addrinfo = await self.resolver.resolve(host, port, af)
  File "/home/daniel/moonraker-env/lib/python3.10/site-packages/tornado/netutil.py", line 433, in resolve
    for fam, _, _, _, address in await asyncio.get_running_loop().getaddrinfo(
  File "/usr/lib/python3.10/asyncio/base_events.py", line 863, in getaddrinfo
    return await self.run_in_executor(
  File "/usr/lib/python3.10/concurrent/futures/thread.py", line 58, in run
    result = self.fn(*self.args, **self.kwargs)
  File "/usr/lib/python3.10/socket.py", line 955, in getaddrinfo
    for res in _socket.getaddrinfo(host, port, family, type, proto, flags):
socket.gaierror: [Errno -3] Temporary failure in name resolution
2024-04-15 09:32:50,101 [proc_stats.py:_watchdog_callback()] - EVENT LOOP BLOCKED: 2698.33 seconds, total blocked count: 134
2024-04-15 09:41:50,033 [proc_stats.py:log_last_stats()] - 
System Time: 1713151465.871197, Usage: 0.31%, Memory: 23556 kB
System Time: 1713159751.401300, Usage: 0.22%, Memory: 23044 kB
System Time: 1713166481.745141, Usage: 0.21%, Memory: 24628 kB
System Time: 1713173027.270582, Usage: 0.21%, Memory: 22792 kB
System Time: 1713178853.299887, Usage: 0.23%, Memory: 22816 kB
