-------------------- Log Start | Tue Feb 25 10:37:17 2025 --------------------
data_path: /home/daniel/printer_data
is_default_data_path: False
config_file: /home/daniel/printer_data/config/moonraker.conf
startup_warnings: []
verbose: False
debug: False
asyncio_debug: False
is_backup_config: False
is_python_package: False
instance_uuid: b58008b63adb40a8a31f7dfdb480fcc5
unix_socket_path: /home/daniel/printer_data/comms/moonraker.sock
software_version: v0.8.0-311-g65a8271
git_branch: master
git_remote: origin
git_repo_url: https://github.com/Arksine/moonraker.git
modified_files: []
unofficial_components: []
log_file: /home/daniel/printer_data/logs/moonraker.log
python_version: 3.10.12 (main, Jan 17 2025, 14:35:34) [GCC 11.4.0]
launch_args: /home/daniel/moonraker-env/bin/python /home/daniel/moonraker/moonraker/moonraker.py -d /home/daniel/printer_data
msgspec_enabled: False
uvloop_enabled: False

#################### Moonraker Configuration ####################

[server]
host = 0.0.0.0
port = 7125
klippy_uds_address = /home/daniel/printer_data/comms/klippy.sock

[authorization]
trusted_clients = 
	10.0.0.0/8
	127.0.0.0/8
	169.254.0.0/16
	172.16.0.0/12
	192.168.0.0/16
	FE80::/10
	::1/128
cors_domains = 
	*.lan
	*.local
	*://localhost
	*://localhost:*
	*://my.mainsail.xyz
	*://app.fluidd.xyz

[octoprint_compat]

[file_manager]
enable_object_processing = True

[power printer_plug]
type = tplink_smartplug
address = 192.168.0.83

[history]

[update_manager]
channel = dev
refresh_interval = 168

[update_manager mainsail-config]
type = git_repo
primary_branch = master
path = ~/mainsail-config
origin = https://github.com/mainsail-crew/mainsail-config.git
managed_services = klipper

[update_manager mainsail]
type = web
channel = stable
repo = mainsail-crew/mainsail
path = ~/mainsail

[update_manager Klipper-Adaptive-Meshing-Purging]
type = git_repo
channel = dev
path = ~/Klipper-Adaptive-Meshing-Purging
origin = https://github.com/kyleisah/Klipper-Adaptive-Meshing-Purging.git
managed_services = klipper
primary_branch = main

[update_manager klipper-backup]
type = git_repo
path = ~/klipper-backup
origin = https://github.com/Staubgeborener/klipper-backup.git
managed_services = moonraker
primary_branch = main

[update_manager crowsnest]
type = git_repo
path = ~/crowsnest
origin = https://github.com/mainsail-crew/crowsnest.git
managed_services = crowsnest
install_script = tools/pkglist.sh

#################################################################
All Configuration Files:
/home/daniel/printer_data/config/moonraker.conf
#################################################################

Database Versions: pylmdb = 1.4.1, lmdb = (0, 9, 29)
Unsafe Shutdown Count: 5

System Info:

***python***
  version: (3, 10, 12, 'final', 0)
  version_string: 3.10.12 (main, Jan 17 2025, 14:35:34) [GCC 11.4.0]

***cpu_info***
  cpu_count: 4
  bits: 64bit
  processor: x86_64
  cpu_desc: Intel(R) Core(TM) i5-5200U CPU @ 2.20GHz
  serial_number: 
  hardware_desc: 
  model: 
  total_memory: 12115824
  memory_units: kB

***sd_info***

***distribution***
  name: Ubuntu 22.04.4 LTS
  id: ubuntu
  version: 22.04
  version_parts: {'major': '22', 'minor': '04', 'build_number': ''}
  like: debian
  codename: jammy
  release_info: {}

***virtualization***
  virt_type: none
  virt_identifier: none

***network***

***canbus***

***Allowed Services***
  klipper_mcu
  webcamd
  MoonCord
  KlipperScreen
  moonraker-telegram-bot
  moonraker-obico
  sonar
  crowsnest
  octoeverywhere
  ratos-configurator
Module libcamera unavailble, import failed

Systemd unit moonraker.service:
unit_name: moonraker.service
is_default: True
manager: systemd
Properties:
**Requires=['network-online.target', 'sysinit.target', 'system.slice', '-.mount']
**After=['basic.target', 'system.slice', 'network-online.target', '-.mount', 'sysinit.target', 'systemd-journald.socket']
**SupplementaryGroups=['moonraker-admin']
**EnvironmentFiles=/home/daniel/printer_data/systemd/moonraker.env
**ExecStart=/home/daniel/moonraker-env/bin/python $MOONRAKER_ARGS
**WorkingDirectory=/home/daniel/moonraker
**FragmentPath=/etc/systemd/system/moonraker.service
**Description=API Server for Klipper SV1
**User=daniel

Systemd unit klipper.service:
unit_name: klipper.service
is_default: True
manager: systemd
Properties:
**Requires=['system.slice', 'sysinit.target', '-.mount']
**After=['sysinit.target', 'systemd-journald.socket', 'system.slice', '-.mount', 'basic.target', 'network-online.target']
**SupplementaryGroups=[]
**EnvironmentFiles=/home/daniel/printer_data/systemd/klipper.env
**ExecStart=/home/daniel/klippy-env/bin/python $KLIPPER_ARGS
**WorkingDirectory=/home/daniel/klipper
**FragmentPath=/etc/systemd/system/klipper.service
**Description=Klipper 3D Printer Firmware SV1
**User=daniel
Git Repo moonraker: No warnings detected
Git Repo klipper: No warnings detected
Git Repo mainsail-config: No warnings detected
Git Repo Klipper-Adaptive-Meshing-Purging: No warnings detected
Git Repo klipper-backup: No warnings detected
Git Repo crowsnest: No warnings detected
Klipper Version: v0.12.0-111-g4f00f219
2025-02-25 05:37:17,865 [announcements.py:_fetch_moonlight()] - Failed to update subscription 'moonraker': Timeout while connecting
2025-02-25 05:37:44,877 [announcements.py:_fetch_moonlight()] - Failed to update subscription 'klipper': Timeout while connecting
2025-02-25 06:07:03,122 [ioloop.py:_run_callback()] - Exception in callback functools.partial(<function _HTTPConnection.__init__.<locals>.<lambda> at 0x7f09c923fd90>, <Task finished name='Task-2609627' coro=<_HTTPConnection.run() done, defined at /home/daniel/moonraker-env/lib/python3.10/site-packages/tornado/simple_httpclient.py:290> exception=gaierror(-3, 'Temporary failure in name resolution')>)
Traceback (most recent call last):
  File "/home/daniel/moonraker-env/lib/python3.10/site-packages/tornado/ioloop.py", line 750, in _run_callback
    ret = callback()
  File "/home/daniel/moonraker-env/lib/python3.10/site-packages/tornado/simple_httpclient.py", line 287, in <lambda>
    gen.convert_yielded(self.run()), lambda f: f.result()
  File "/home/daniel/moonraker-env/lib/python3.10/site-packages/tornado/simple_httpclient.py", line 340, in run
    stream = await self.tcp_client.connect(
  File "/home/daniel/moonraker-env/lib/python3.10/site-packages/tornado/tcpclient.py", line 269, in connect
    addrinfo = await self.resolver.resolve(host, port, af)
  File "/home/daniel/moonraker-env/lib/python3.10/site-packages/tornado/netutil.py", line 433, in resolve
    for fam, _, _, _, address in await asyncio.get_running_loop().getaddrinfo(
  File "/usr/lib/python3.10/asyncio/base_events.py", line 863, in getaddrinfo
    return await self.run_in_executor(
  File "/usr/lib/python3.10/concurrent/futures/thread.py", line 58, in run
    result = self.fn(*self.args, **self.kwargs)
  File "/usr/lib/python3.10/socket.py", line 955, in getaddrinfo
    for res in _socket.getaddrinfo(host, port, family, type, proto, flags):
socket.gaierror: [Errno -3] Temporary failure in name resolution
2025-02-25 06:07:06,193 [ioloop.py:_run_callback()] - Exception in callback functools.partial(<function _HTTPConnection.__init__.<locals>.<lambda> at 0x7f09c8948160>, <Task finished name='Task-2609655' coro=<_HTTPConnection.run() done, defined at /home/daniel/moonraker-env/lib/python3.10/site-packages/tornado/simple_httpclient.py:290> exception=gaierror(-3, 'Temporary failure in name resolution')>)
Traceback (most recent call last):
  File "/home/daniel/moonraker-env/lib/python3.10/site-packages/tornado/ioloop.py", line 750, in _run_callback
    ret = callback()
  File "/home/daniel/moonraker-env/lib/python3.10/site-packages/tornado/simple_httpclient.py", line 287, in <lambda>
    gen.convert_yielded(self.run()), lambda f: f.result()
  File "/home/daniel/moonraker-env/lib/python3.10/site-packages/tornado/simple_httpclient.py", line 340, in run
    stream = await self.tcp_client.connect(
  File "/home/daniel/moonraker-env/lib/python3.10/site-packages/tornado/tcpclient.py", line 269, in connect
    addrinfo = await self.resolver.resolve(host, port, af)
  File "/home/daniel/moonraker-env/lib/python3.10/site-packages/tornado/netutil.py", line 433, in resolve
    for fam, _, _, _, address in await asyncio.get_running_loop().getaddrinfo(
  File "/usr/lib/python3.10/asyncio/base_events.py", line 863, in getaddrinfo
    return await self.run_in_executor(
  File "/usr/lib/python3.10/concurrent/futures/thread.py", line 58, in run
    result = self.fn(*self.args, **self.kwargs)
  File "/usr/lib/python3.10/socket.py", line 955, in getaddrinfo
    for res in _socket.getaddrinfo(host, port, family, type, proto, flags):
socket.gaierror: [Errno -3] Temporary failure in name resolution
2025-02-25 06:07:12,338 [ioloop.py:_run_callback()] - Exception in callback functools.partial(<function _HTTPConnection.__init__.<locals>.<lambda> at 0x7f09c8948700>, <Task finished name='Task-2609673' coro=<_HTTPConnection.run() done, defined at /home/daniel/moonraker-env/lib/python3.10/site-packages/tornado/simple_httpclient.py:290> exception=gaierror(-3, 'Temporary failure in name resolution')>)
Traceback (most recent call last):
  File "/home/daniel/moonraker-env/lib/python3.10/site-packages/tornado/ioloop.py", line 750, in _run_callback
    ret = callback()
  File "/home/daniel/moonraker-env/lib/python3.10/site-packages/tornado/simple_httpclient.py", line 287, in <lambda>
    gen.convert_yielded(self.run()), lambda f: f.result()
  File "/home/daniel/moonraker-env/lib/python3.10/site-packages/tornado/simple_httpclient.py", line 340, in run
    stream = await self.tcp_client.connect(
  File "/home/daniel/moonraker-env/lib/python3.10/site-packages/tornado/tcpclient.py", line 269, in connect
    addrinfo = await self.resolver.resolve(host, port, af)
  File "/home/daniel/moonraker-env/lib/python3.10/site-packages/tornado/netutil.py", line 433, in resolve
    for fam, _, _, _, address in await asyncio.get_running_loop().getaddrinfo(
  File "/usr/lib/python3.10/asyncio/base_events.py", line 863, in getaddrinfo
    return await self.run_in_executor(
  File "/usr/lib/python3.10/concurrent/futures/thread.py", line 58, in run
    result = self.fn(*self.args, **self.kwargs)
  File "/usr/lib/python3.10/socket.py", line 955, in getaddrinfo
    for res in _socket.getaddrinfo(host, port, family, type, proto, flags):
socket.gaierror: [Errno -3] Temporary failure in name resolution
2025-02-25 06:07:17,864 [announcements.py:_fetch_moonlight()] - Failed to update subscription 'moonraker': Timeout while connecting
2025-02-25 06:07:18,481 [ioloop.py:_run_callback()] - Exception in callback functools.partial(<function _HTTPConnection.__init__.<locals>.<lambda> at 0x7f09c89484c0>, <Task finished name='Task-2609700' coro=<_HTTPConnection.run() done, defined at /home/daniel/moonraker-env/lib/python3.10/site-packages/tornado/simple_httpclient.py:290> exception=gaierror(-3, 'Temporary failure in name resolution')>)
Traceback (most recent call last):
  File "/home/daniel/moonraker-env/lib/python3.10/site-packages/tornado/ioloop.py", line 750, in _run_callback
    ret = callback()
  File "/home/daniel/moonraker-env/lib/python3.10/site-packages/tornado/simple_httpclient.py", line 287, in <lambda>
    gen.convert_yielded(self.run()), lambda f: f.result()
  File "/home/daniel/moonraker-env/lib/python3.10/site-packages/tornado/simple_httpclient.py", line 340, in run
    stream = await self.tcp_client.connect(
  File "/home/daniel/moonraker-env/lib/python3.10/site-packages/tornado/tcpclient.py", line 269, in connect
    addrinfo = await self.resolver.resolve(host, port, af)
  File "/home/daniel/moonraker-env/lib/python3.10/site-packages/tornado/netutil.py", line 433, in resolve
    for fam, _, _, _, address in await asyncio.get_running_loop().getaddrinfo(
  File "/usr/lib/python3.10/asyncio/base_events.py", line 863, in getaddrinfo
    return await self.run_in_executor(
  File "/usr/lib/python3.10/concurrent/futures/thread.py", line 58, in run
    result = self.fn(*self.args, **self.kwargs)
  File "/usr/lib/python3.10/socket.py", line 955, in getaddrinfo
    for res in _socket.getaddrinfo(host, port, family, type, proto, flags):
socket.gaierror: [Errno -3] Temporary failure in name resolution
2025-02-25 06:07:24,626 [ioloop.py:_run_callback()] - Exception in callback functools.partial(<function _HTTPConnection.__init__.<locals>.<lambda> at 0x7f09c8948820>, <Task finished name='Task-2609719' coro=<_HTTPConnection.run() done, defined at /home/daniel/moonraker-env/lib/python3.10/site-packages/tornado/simple_httpclient.py:290> exception=gaierror(-3, 'Temporary failure in name resolution')>)
Traceback (most recent call last):
  File "/home/daniel/moonraker-env/lib/python3.10/site-packages/tornado/ioloop.py", line 750, in _run_callback
    ret = callback()
  File "/home/daniel/moonraker-env/lib/python3.10/site-packages/tornado/simple_httpclient.py", line 287, in <lambda>
    gen.convert_yielded(self.run()), lambda f: f.result()
  File "/home/daniel/moonraker-env/lib/python3.10/site-packages/tornado/simple_httpclient.py", line 340, in run
    stream = await self.tcp_client.connect(
  File "/home/daniel/moonraker-env/lib/python3.10/site-packages/tornado/tcpclient.py", line 269, in connect
    addrinfo = await self.resolver.resolve(host, port, af)
  File "/home/daniel/moonraker-env/lib/python3.10/site-packages/tornado/netutil.py", line 433, in resolve
    for fam, _, _, _, address in await asyncio.get_running_loop().getaddrinfo(
  File "/usr/lib/python3.10/asyncio/base_events.py", line 863, in getaddrinfo
    return await self.run_in_executor(
  File "/usr/lib/python3.10/concurrent/futures/thread.py", line 58, in run
    result = self.fn(*self.args, **self.kwargs)
  File "/usr/lib/python3.10/socket.py", line 955, in getaddrinfo
    for res in _socket.getaddrinfo(host, port, family, type, proto, flags):
socket.gaierror: [Errno -3] Temporary failure in name resolution
2025-02-25 06:07:27,698 [ioloop.py:_run_callback()] - Exception in callback functools.partial(<function _HTTPConnection.__init__.<locals>.<lambda> at 0x7f09c89940d0>, <Task finished name='Task-2609742' coro=<_HTTPConnection.run() done, defined at /home/daniel/moonraker-env/lib/python3.10/site-packages/tornado/simple_httpclient.py:290> exception=gaierror(-3, 'Temporary failure in name resolution')>)
Traceback (most recent call last):
  File "/home/daniel/moonraker-env/lib/python3.10/site-packages/tornado/ioloop.py", line 750, in _run_callback
    ret = callback()
  File "/home/daniel/moonraker-env/lib/python3.10/site-packages/tornado/simple_httpclient.py", line 287, in <lambda>
    gen.convert_yielded(self.run()), lambda f: f.result()
  File "/home/daniel/moonraker-env/lib/python3.10/site-packages/tornado/simple_httpclient.py", line 340, in run
    stream = await self.tcp_client.connect(
  File "/home/daniel/moonraker-env/lib/python3.10/site-packages/tornado/tcpclient.py", line 269, in connect
    addrinfo = await self.resolver.resolve(host, port, af)
  File "/home/daniel/moonraker-env/lib/python3.10/site-packages/tornado/netutil.py", line 433, in resolve
    for fam, _, _, _, address in await asyncio.get_running_loop().getaddrinfo(
  File "/usr/lib/python3.10/asyncio/base_events.py", line 863, in getaddrinfo
    return await self.run_in_executor(
  File "/usr/lib/python3.10/concurrent/futures/thread.py", line 58, in run
    result = self.fn(*self.args, **self.kwargs)
  File "/usr/lib/python3.10/socket.py", line 955, in getaddrinfo
    for res in _socket.getaddrinfo(host, port, family, type, proto, flags):
socket.gaierror: [Errno -3] Temporary failure in name resolution
2025-02-25 06:07:33,842 [ioloop.py:_run_callback()] - Exception in callback functools.partial(<function _HTTPConnection.__init__.<locals>.<lambda> at 0x7f09c8948310>, <Task finished name='Task-2609764' coro=<_HTTPConnection.run() done, defined at /home/daniel/moonraker-env/lib/python3.10/site-packages/tornado/simple_httpclient.py:290> exception=gaierror(-3, 'Temporary failure in name resolution')>)
Traceback (most recent call last):
  File "/home/daniel/moonraker-env/lib/python3.10/site-packages/tornado/ioloop.py", line 750, in _run_callback
    ret = callback()
  File "/home/daniel/moonraker-env/lib/python3.10/site-packages/tornado/simple_httpclient.py", line 287, in <lambda>
    gen.convert_yielded(self.run()), lambda f: f.result()
  File "/home/daniel/moonraker-env/lib/python3.10/site-packages/tornado/simple_httpclient.py", line 340, in run
    stream = await self.tcp_client.connect(
  File "/home/daniel/moonraker-env/lib/python3.10/site-packages/tornado/tcpclient.py", line 269, in connect
    addrinfo = await self.resolver.resolve(host, port, af)
  File "/home/daniel/moonraker-env/lib/python3.10/site-packages/tornado/netutil.py", line 433, in resolve
    for fam, _, _, _, address in await asyncio.get_running_loop().getaddrinfo(
  File "/usr/lib/python3.10/asyncio/base_events.py", line 863, in getaddrinfo
    return await self.run_in_executor(
  File "/usr/lib/python3.10/concurrent/futures/thread.py", line 58, in run
    result = self.fn(*self.args, **self.kwargs)
  File "/usr/lib/python3.10/socket.py", line 955, in getaddrinfo
    for res in _socket.getaddrinfo(host, port, family, type, proto, flags):
socket.gaierror: [Errno -3] Temporary failure in name resolution
2025-02-25 06:07:39,986 [ioloop.py:_run_callback()] - Exception in callback functools.partial(<function _HTTPConnection.__init__.<locals>.<lambda> at 0x7f09c8948940>, <Task finished name='Task-2609788' coro=<_HTTPConnection.run() done, defined at /home/daniel/moonraker-env/lib/python3.10/site-packages/tornado/simple_httpclient.py:290> exception=gaierror(-3, 'Temporary failure in name resolution')>)
Traceback (most recent call last):
  File "/home/daniel/moonraker-env/lib/python3.10/site-packages/tornado/ioloop.py", line 750, in _run_callback
    ret = callback()
  File "/home/daniel/moonraker-env/lib/python3.10/site-packages/tornado/simple_httpclient.py", line 287, in <lambda>
    gen.convert_yielded(self.run()), lambda f: f.result()
  File "/home/daniel/moonraker-env/lib/python3.10/site-packages/tornado/simple_httpclient.py", line 340, in run
    stream = await self.tcp_client.connect(
  File "/home/daniel/moonraker-env/lib/python3.10/site-packages/tornado/tcpclient.py", line 269, in connect
    addrinfo = await self.resolver.resolve(host, port, af)
  File "/home/daniel/moonraker-env/lib/python3.10/site-packages/tornado/netutil.py", line 433, in resolve
    for fam, _, _, _, address in await asyncio.get_running_loop().getaddrinfo(
  File "/usr/lib/python3.10/asyncio/base_events.py", line 863, in getaddrinfo
    return await self.run_in_executor(
  File "/usr/lib/python3.10/concurrent/futures/thread.py", line 58, in run
    result = self.fn(*self.args, **self.kwargs)
  File "/usr/lib/python3.10/socket.py", line 955, in getaddrinfo
    for res in _socket.getaddrinfo(host, port, family, type, proto, flags):
socket.gaierror: [Errno -3] Temporary failure in name resolution
2025-02-25 06:07:44,874 [announcements.py:_fetch_moonlight()] - Failed to update subscription 'klipper': Timeout while connecting
2025-02-25 06:07:46,129 [ioloop.py:_run_callback()] - Exception in callback functools.partial(<function _HTTPConnection.__init__.<locals>.<lambda> at 0x7f09c89483a0>, <Task finished name='Task-2609815' coro=<_HTTPConnection.run() done, defined at /home/daniel/moonraker-env/lib/python3.10/site-packages/tornado/simple_httpclient.py:290> exception=gaierror(-3, 'Temporary failure in name resolution')>)
Traceback (most recent call last):
  File "/home/daniel/moonraker-env/lib/python3.10/site-packages/tornado/ioloop.py", line 750, in _run_callback
    ret = callback()
  File "/home/daniel/moonraker-env/lib/python3.10/site-packages/tornado/simple_httpclient.py", line 287, in <lambda>
    gen.convert_yielded(self.run()), lambda f: f.result()
  File "/home/daniel/moonraker-env/lib/python3.10/site-packages/tornado/simple_httpclient.py", line 340, in run
    stream = await self.tcp_client.connect(
  File "/home/daniel/moonraker-env/lib/python3.10/site-packages/tornado/tcpclient.py", line 269, in connect
    addrinfo = await self.resolver.resolve(host, port, af)
  File "/home/daniel/moonraker-env/lib/python3.10/site-packages/tornado/netutil.py", line 433, in resolve
    for fam, _, _, _, address in await asyncio.get_running_loop().getaddrinfo(
  File "/usr/lib/python3.10/asyncio/base_events.py", line 863, in getaddrinfo
    return await self.run_in_executor(
  File "/usr/lib/python3.10/concurrent/futures/thread.py", line 58, in run
    result = self.fn(*self.args, **self.kwargs)
  File "/usr/lib/python3.10/socket.py", line 955, in getaddrinfo
    for res in _socket.getaddrinfo(host, port, family, type, proto, flags):
socket.gaierror: [Errno -3] Temporary failure in name resolution
2025-02-25 06:07:49,201 [ioloop.py:_run_callback()] - Exception in callback functools.partial(<function _HTTPConnection.__init__.<locals>.<lambda> at 0x7f09c89944c0>, <Task finished name='Task-2609833' coro=<_HTTPConnection.run() done, defined at /home/daniel/moonraker-env/lib/python3.10/site-packages/tornado/simple_httpclient.py:290> exception=gaierror(-3, 'Temporary failure in name resolution')>)
Traceback (most recent call last):
  File "/home/daniel/moonraker-env/lib/python3.10/site-packages/tornado/ioloop.py", line 750, in _run_callback
    ret = callback()
  File "/home/daniel/moonraker-env/lib/python3.10/site-packages/tornado/simple_httpclient.py", line 287, in <lambda>
    gen.convert_yielded(self.run()), lambda f: f.result()
  File "/home/daniel/moonraker-env/lib/python3.10/site-packages/tornado/simple_httpclient.py", line 340, in run
    stream = await self.tcp_client.connect(
  File "/home/daniel/moonraker-env/lib/python3.10/site-packages/tornado/tcpclient.py", line 269, in connect
    addrinfo = await self.resolver.resolve(host, port, af)
  File "/home/daniel/moonraker-env/lib/python3.10/site-packages/tornado/netutil.py", line 433, in resolve
    for fam, _, _, _, address in await asyncio.get_running_loop().getaddrinfo(
  File "/usr/lib/python3.10/asyncio/base_events.py", line 863, in getaddrinfo
    return await self.run_in_executor(
  File "/usr/lib/python3.10/concurrent/futures/thread.py", line 58, in run
    result = self.fn(*self.args, **self.kwargs)
  File "/usr/lib/python3.10/socket.py", line 955, in getaddrinfo
    for res in _socket.getaddrinfo(host, port, family, type, proto, flags):
socket.gaierror: [Errno -3] Temporary failure in name resolution
2025-02-25 06:37:03,122 [ioloop.py:_run_callback()] - Exception in callback functools.partial(<function _HTTPConnection.__init__.<locals>.<lambda> at 0x7f09c923fd90>, <Task finished name='Task-2616837' coro=<_HTTPConnection.run() done, defined at /home/daniel/moonraker-env/lib/python3.10/site-packages/tornado/simple_httpclient.py:290> exception=gaierror(-3, 'Temporary failure in name resolution')>)
Traceback (most recent call last):
  File "/home/daniel/moonraker-env/lib/python3.10/site-packages/tornado/ioloop.py", line 750, in _run_callback
    ret = callback()
  File "/home/daniel/moonraker-env/lib/python3.10/site-packages/tornado/simple_httpclient.py", line 287, in <lambda>
    gen.convert_yielded(self.run()), lambda f: f.result()
  File "/home/daniel/moonraker-env/lib/python3.10/site-packages/tornado/simple_httpclient.py", line 340, in run
    stream = await self.tcp_client.connect(
  File "/home/daniel/moonraker-env/lib/python3.10/site-packages/tornado/tcpclient.py", line 269, in connect
    addrinfo = await self.resolver.resolve(host, port, af)
  File "/home/daniel/moonraker-env/lib/python3.10/site-packages/tornado/netutil.py", line 433, in resolve
    for fam, _, _, _, address in await asyncio.get_running_loop().getaddrinfo(
  File "/usr/lib/python3.10/asyncio/base_events.py", line 863, in getaddrinfo
    return await self.run_in_executor(
  File "/usr/lib/python3.10/concurrent/futures/thread.py", line 58, in run
    result = self.fn(*self.args, **self.kwargs)
  File "/usr/lib/python3.10/socket.py", line 955, in getaddrinfo
    for res in _socket.getaddrinfo(host, port, family, type, proto, flags):
socket.gaierror: [Errno -3] Temporary failure in name resolution
2025-02-25 06:37:06,194 [ioloop.py:_run_callback()] - Exception in callback functools.partial(<function _HTTPConnection.__init__.<locals>.<lambda> at 0x7f09c89481f0>, <Task finished name='Task-2616857' coro=<_HTTPConnection.run() done, defined at /home/daniel/moonraker-env/lib/python3.10/site-packages/tornado/simple_httpclient.py:290> exception=gaierror(-3, 'Temporary failure in name resolution')>)
Traceback (most recent call last):
  File "/home/daniel/moonraker-env/lib/python3.10/site-packages/tornado/ioloop.py", line 750, in _run_callback
    ret = callback()
  File "/home/daniel/moonraker-env/lib/python3.10/site-packages/tornado/simple_httpclient.py", line 287, in <lambda>
    gen.convert_yielded(self.run()), lambda f: f.result()
  File "/home/daniel/moonraker-env/lib/python3.10/site-packages/tornado/simple_httpclient.py", line 340, in run
    stream = await self.tcp_client.connect(
  File "/home/daniel/moonraker-env/lib/python3.10/site-packages/tornado/tcpclient.py", line 269, in connect
    addrinfo = await self.resolver.resolve(host, port, af)
  File "/home/daniel/moonraker-env/lib/python3.10/site-packages/tornado/netutil.py", line 433, in resolve
    for fam, _, _, _, address in await asyncio.get_running_loop().getaddrinfo(
  File "/usr/lib/python3.10/asyncio/base_events.py", line 863, in getaddrinfo
    return await self.run_in_executor(
  File "/usr/lib/python3.10/concurrent/futures/thread.py", line 58, in run
    result = self.fn(*self.args, **self.kwargs)
  File "/usr/lib/python3.10/socket.py", line 955, in getaddrinfo
    for res in _socket.getaddrinfo(host, port, family, type, proto, flags):
socket.gaierror: [Errno -3] Temporary failure in name resolution
2025-02-25 06:37:12,337 [ioloop.py:_run_callback()] - Exception in callback functools.partial(<function _HTTPConnection.__init__.<locals>.<lambda> at 0x7f09c8994160>, <Task finished name='Task-2616884' coro=<_HTTPConnection.run() done, defined at /home/daniel/moonraker-env/lib/python3.10/site-packages/tornado/simple_httpclient.py:290> exception=gaierror(-3, 'Temporary failure in name resolution')>)
Traceback (most recent call last):
  File "/home/daniel/moonraker-env/lib/python3.10/site-packages/tornado/ioloop.py", line 750, in _run_callback
    ret = callback()
  File "/home/daniel/moonraker-env/lib/python3.10/site-packages/tornado/simple_httpclient.py", line 287, in <lambda>
    gen.convert_yielded(self.run()), lambda f: f.result()
  File "/home/daniel/moonraker-env/lib/python3.10/site-packages/tornado/simple_httpclient.py", line 340, in run
    stream = await self.tcp_client.connect(
  File "/home/daniel/moonraker-env/lib/python3.10/site-packages/tornado/tcpclient.py", line 269, in connect
    addrinfo = await self.resolver.resolve(host, port, af)
  File "/home/daniel/moonraker-env/lib/python3.10/site-packages/tornado/netutil.py", line 433, in resolve
    for fam, _, _, _, address in await asyncio.get_running_loop().getaddrinfo(
  File "/usr/lib/python3.10/asyncio/base_events.py", line 863, in getaddrinfo
    return await self.run_in_executor(
  File "/usr/lib/python3.10/concurrent/futures/thread.py", line 58, in run
    result = self.fn(*self.args, **self.kwargs)
  File "/usr/lib/python3.10/socket.py", line 955, in getaddrinfo
    for res in _socket.getaddrinfo(host, port, family, type, proto, flags):
socket.gaierror: [Errno -3] Temporary failure in name resolution
2025-02-25 06:37:17,865 [announcements.py:_fetch_moonlight()] - Failed to update subscription 'moonraker': Timeout while connecting
2025-02-25 06:37:18,481 [ioloop.py:_run_callback()] - Exception in callback functools.partial(<function _HTTPConnection.__init__.<locals>.<lambda> at 0x7f09c89488b0>, <Task finished name='Task-2616907' coro=<_HTTPConnection.run() done, defined at /home/daniel/moonraker-env/lib/python3.10/site-packages/tornado/simple_httpclient.py:290> exception=gaierror(-3, 'Temporary failure in name resolution')>)
Traceback (most recent call last):
  File "/home/daniel/moonraker-env/lib/python3.10/site-packages/tornado/ioloop.py", line 750, in _run_callback
    ret = callback()
  File "/home/daniel/moonraker-env/lib/python3.10/site-packages/tornado/simple_httpclient.py", line 287, in <lambda>
    gen.convert_yielded(self.run()), lambda f: f.result()
  File "/home/daniel/moonraker-env/lib/python3.10/site-packages/tornado/simple_httpclient.py", line 340, in run
    stream = await self.tcp_client.connect(
  File "/home/daniel/moonraker-env/lib/python3.10/site-packages/tornado/tcpclient.py", line 269, in connect
    addrinfo = await self.resolver.resolve(host, port, af)
  File "/home/daniel/moonraker-env/lib/python3.10/site-packages/tornado/netutil.py", line 433, in resolve
    for fam, _, _, _, address in await asyncio.get_running_loop().getaddrinfo(
  File "/usr/lib/python3.10/asyncio/base_events.py", line 863, in getaddrinfo
    return await self.run_in_executor(
  File "/usr/lib/python3.10/concurrent/futures/thread.py", line 58, in run
    result = self.fn(*self.args, **self.kwargs)
  File "/usr/lib/python3.10/socket.py", line 955, in getaddrinfo
    for res in _socket.getaddrinfo(host, port, family, type, proto, flags):
socket.gaierror: [Errno -3] Temporary failure in name resolution
2025-02-25 06:37:24,626 [ioloop.py:_run_callback()] - Exception in callback functools.partial(<function _HTTPConnection.__init__.<locals>.<lambda> at 0x7f09c89489d0>, <Task finished name='Task-2616929' coro=<_HTTPConnection.run() done, defined at /home/daniel/moonraker-env/lib/python3.10/site-packages/tornado/simple_httpclient.py:290> exception=gaierror(-3, 'Temporary failure in name resolution')>)
Traceback (most recent call last):
  File "/home/daniel/moonraker-env/lib/python3.10/site-packages/tornado/ioloop.py", line 750, in _run_callback
    ret = callback()
  File "/home/daniel/moonraker-env/lib/python3.10/site-packages/tornado/simple_httpclient.py", line 287, in <lambda>
    gen.convert_yielded(self.run()), lambda f: f.result()
  File "/home/daniel/moonraker-env/lib/python3.10/site-packages/tornado/simple_httpclient.py", line 340, in run
    stream = await self.tcp_client.connect(
  File "/home/daniel/moonraker-env/lib/python3.10/site-packages/tornado/tcpclient.py", line 269, in connect
    addrinfo = await self.resolver.resolve(host, port, af)
  File "/home/daniel/moonraker-env/lib/python3.10/site-packages/tornado/netutil.py", line 433, in resolve
    for fam, _, _, _, address in await asyncio.get_running_loop().getaddrinfo(
  File "/usr/lib/python3.10/asyncio/base_events.py", line 863, in getaddrinfo
    return await self.run_in_executor(
  File "/usr/lib/python3.10/concurrent/futures/thread.py", line 58, in run
    result = self.fn(*self.args, **self.kwargs)
  File "/usr/lib/python3.10/socket.py", line 955, in getaddrinfo
    for res in _socket.getaddrinfo(host, port, family, type, proto, flags):
socket.gaierror: [Errno -3] Temporary failure in name resolution
2025-02-25 06:37:27,698 [ioloop.py:_run_callback()] - Exception in callback functools.partial(<function _HTTPConnection.__init__.<locals>.<lambda> at 0x7f09c8994280>, <Task finished name='Task-2616953' coro=<_HTTPConnection.run() done, defined at /home/daniel/moonraker-env/lib/python3.10/site-packages/tornado/simple_httpclient.py:290> exception=gaierror(-3, 'Temporary failure in name resolution')>)
Traceback (most recent call last):
  File "/home/daniel/moonraker-env/lib/python3.10/site-packages/tornado/ioloop.py", line 750, in _run_callback
    ret = callback()
  File "/home/daniel/moonraker-env/lib/python3.10/site-packages/tornado/simple_httpclient.py", line 287, in <lambda>
    gen.convert_yielded(self.run()), lambda f: f.result()
  File "/home/daniel/moonraker-env/lib/python3.10/site-packages/tornado/simple_httpclient.py", line 340, in run
    stream = await self.tcp_client.connect(
  File "/home/daniel/moonraker-env/lib/python3.10/site-packages/tornado/tcpclient.py", line 269, in connect
    addrinfo = await self.resolver.resolve(host, port, af)
  File "/home/daniel/moonraker-env/lib/python3.10/site-packages/tornado/netutil.py", line 433, in resolve
    for fam, _, _, _, address in await asyncio.get_running_loop().getaddrinfo(
  File "/usr/lib/python3.10/asyncio/base_events.py", line 863, in getaddrinfo
    return await self.run_in_executor(
  File "/usr/lib/python3.10/concurrent/futures/thread.py", line 58, in run
    result = self.fn(*self.args, **self.kwargs)
  File "/usr/lib/python3.10/socket.py", line 955, in getaddrinfo
    for res in _socket.getaddrinfo(host, port, family, type, proto, flags):
socket.gaierror: [Errno -3] Temporary failure in name resolution
2025-02-25 06:37:33,841 [ioloop.py:_run_callback()] - Exception in callback functools.partial(<function _HTTPConnection.__init__.<locals>.<lambda> at 0x7f09c8948160>, <Task finished name='Task-2616971' coro=<_HTTPConnection.run() done, defined at /home/daniel/moonraker-env/lib/python3.10/site-packages/tornado/simple_httpclient.py:290> exception=gaierror(-3, 'Temporary failure in name resolution')>)
Traceback (most recent call last):
  File "/home/daniel/moonraker-env/lib/python3.10/site-packages/tornado/ioloop.py", line 750, in _run_callback
    ret = callback()
  File "/home/daniel/moonraker-env/lib/python3.10/site-packages/tornado/simple_httpclient.py", line 287, in <lambda>
    gen.convert_yielded(self.run()), lambda f: f.result()
  File "/home/daniel/moonraker-env/lib/python3.10/site-packages/tornado/simple_httpclient.py", line 340, in run
    stream = await self.tcp_client.connect(
  File "/home/daniel/moonraker-env/lib/python3.10/site-packages/tornado/tcpclient.py", line 269, in connect
    addrinfo = await self.resolver.resolve(host, port, af)
  File "/home/daniel/moonraker-env/lib/python3.10/site-packages/tornado/netutil.py", line 433, in resolve
    for fam, _, _, _, address in await asyncio.get_running_loop().getaddrinfo(
  File "/usr/lib/python3.10/asyncio/base_events.py", line 863, in getaddrinfo
    return await self.run_in_executor(
  File "/usr/lib/python3.10/concurrent/futures/thread.py", line 58, in run
    result = self.fn(*self.args, **self.kwargs)
  File "/usr/lib/python3.10/socket.py", line 955, in getaddrinfo
    for res in _socket.getaddrinfo(host, port, family, type, proto, flags):
socket.gaierror: [Errno -3] Temporary failure in name resolution
2025-02-25 06:37:39,986 [ioloop.py:_run_callback()] - Exception in callback functools.partial(<function _HTTPConnection.__init__.<locals>.<lambda> at 0x7f09c923e050>, <Task finished name='Task-2616998' coro=<_HTTPConnection.run() done, defined at /home/daniel/moonraker-env/lib/python3.10/site-packages/tornado/simple_httpclient.py:290> exception=gaierror(-3, 'Temporary failure in name resolution')>)
Traceback (most recent call last):
  File "/home/daniel/moonraker-env/lib/python3.10/site-packages/tornado/ioloop.py", line 750, in _run_callback
    ret = callback()
  File "/home/daniel/moonraker-env/lib/python3.10/site-packages/tornado/simple_httpclient.py", line 287, in <lambda>
    gen.convert_yielded(self.run()), lambda f: f.result()
  File "/home/daniel/moonraker-env/lib/python3.10/site-packages/tornado/simple_httpclient.py", line 340, in run
    stream = await self.tcp_client.connect(
  File "/home/daniel/moonraker-env/lib/python3.10/site-packages/tornado/tcpclient.py", line 269, in connect
    addrinfo = await self.resolver.resolve(host, port, af)
  File "/home/daniel/moonraker-env/lib/python3.10/site-packages/tornado/netutil.py", line 433, in resolve
    for fam, _, _, _, address in await asyncio.get_running_loop().getaddrinfo(
  File "/usr/lib/python3.10/asyncio/base_events.py", line 863, in getaddrinfo
    return await self.run_in_executor(
  File "/usr/lib/python3.10/concurrent/futures/thread.py", line 58, in run
    result = self.fn(*self.args, **self.kwargs)
  File "/usr/lib/python3.10/socket.py", line 955, in getaddrinfo
    for res in _socket.getaddrinfo(host, port, family, type, proto, flags):
socket.gaierror: [Errno -3] Temporary failure in name resolution
2025-02-25 06:37:44,877 [announcements.py:_fetch_moonlight()] - Failed to update subscription 'klipper': Timeout while connecting
2025-02-25 06:37:46,130 [ioloop.py:_run_callback()] - Exception in callback functools.partial(<function _HTTPConnection.__init__.<locals>.<lambda> at 0x7f09c8948700>, <Task finished name='Task-2617017' coro=<_HTTPConnection.run() done, defined at /home/daniel/moonraker-env/lib/python3.10/site-packages/tornado/simple_httpclient.py:290> exception=gaierror(-3, 'Temporary failure in name resolution')>)
Traceback (most recent call last):
  File "/home/daniel/moonraker-env/lib/python3.10/site-packages/tornado/ioloop.py", line 750, in _run_callback
    ret = callback()
  File "/home/daniel/moonraker-env/lib/python3.10/site-packages/tornado/simple_httpclient.py", line 287, in <lambda>
    gen.convert_yielded(self.run()), lambda f: f.result()
  File "/home/daniel/moonraker-env/lib/python3.10/site-packages/tornado/simple_httpclient.py", line 340, in run
    stream = await self.tcp_client.connect(
  File "/home/daniel/moonraker-env/lib/python3.10/site-packages/tornado/tcpclient.py", line 269, in connect
    addrinfo = await self.resolver.resolve(host, port, af)
  File "/home/daniel/moonraker-env/lib/python3.10/site-packages/tornado/netutil.py", line 433, in resolve
    for fam, _, _, _, address in await asyncio.get_running_loop().getaddrinfo(
  File "/usr/lib/python3.10/asyncio/base_events.py", line 863, in getaddrinfo
    return await self.run_in_executor(
  File "/usr/lib/python3.10/concurrent/futures/thread.py", line 58, in run
    result = self.fn(*self.args, **self.kwargs)
  File "/usr/lib/python3.10/socket.py", line 955, in getaddrinfo
    for res in _socket.getaddrinfo(host, port, family, type, proto, flags):
socket.gaierror: [Errno -3] Temporary failure in name resolution
2025-02-25 06:37:49,201 [ioloop.py:_run_callback()] - Exception in callback functools.partial(<function _HTTPConnection.__init__.<locals>.<lambda> at 0x7f09c8994430>, <Task finished name='Task-2617044' coro=<_HTTPConnection.run() done, defined at /home/daniel/moonraker-env/lib/python3.10/site-packages/tornado/simple_httpclient.py:290> exception=gaierror(-3, 'Temporary failure in name resolution')>)
Traceback (most recent call last):
  File "/home/daniel/moonraker-env/lib/python3.10/site-packages/tornado/ioloop.py", line 750, in _run_callback
    ret = callback()
  File "/home/daniel/moonraker-env/lib/python3.10/site-packages/tornado/simple_httpclient.py", line 287, in <lambda>
    gen.convert_yielded(self.run()), lambda f: f.result()
  File "/home/daniel/moonraker-env/lib/python3.10/site-packages/tornado/simple_httpclient.py", line 340, in run
    stream = await self.tcp_client.connect(
  File "/home/daniel/moonraker-env/lib/python3.10/site-packages/tornado/tcpclient.py", line 269, in connect
    addrinfo = await self.resolver.resolve(host, port, af)
  File "/home/daniel/moonraker-env/lib/python3.10/site-packages/tornado/netutil.py", line 433, in resolve
    for fam, _, _, _, address in await asyncio.get_running_loop().getaddrinfo(
  File "/usr/lib/python3.10/asyncio/base_events.py", line 863, in getaddrinfo
    return await self.run_in_executor(
  File "/usr/lib/python3.10/concurrent/futures/thread.py", line 58, in run
    result = self.fn(*self.args, **self.kwargs)
  File "/usr/lib/python3.10/socket.py", line 955, in getaddrinfo
    for res in _socket.getaddrinfo(host, port, family, type, proto, flags):
socket.gaierror: [Errno -3] Temporary failure in name resolution
2025-02-25 07:07:03,154 [ioloop.py:_run_callback()] - Exception in callback functools.partial(<function _HTTPConnection.__init__.<locals>.<lambda> at 0x7f09c894bf40>, <Task finished name='Task-2624045' coro=<_HTTPConnection.run() done, defined at /home/daniel/moonraker-env/lib/python3.10/site-packages/tornado/simple_httpclient.py:290> exception=gaierror(-3, 'Temporary failure in name resolution')>)
Traceback (most recent call last):
  File "/home/daniel/moonraker-env/lib/python3.10/site-packages/tornado/ioloop.py", line 750, in _run_callback
    ret = callback()
  File "/home/daniel/moonraker-env/lib/python3.10/site-packages/tornado/simple_httpclient.py", line 287, in <lambda>
    gen.convert_yielded(self.run()), lambda f: f.result()
  File "/home/daniel/moonraker-env/lib/python3.10/site-packages/tornado/simple_httpclient.py", line 340, in run
    stream = await self.tcp_client.connect(
  File "/home/daniel/moonraker-env/lib/python3.10/site-packages/tornado/tcpclient.py", line 269, in connect
    addrinfo = await self.resolver.resolve(host, port, af)
  File "/home/daniel/moonraker-env/lib/python3.10/site-packages/tornado/netutil.py", line 433, in resolve
    for fam, _, _, _, address in await asyncio.get_running_loop().getaddrinfo(
  File "/usr/lib/python3.10/asyncio/base_events.py", line 863, in getaddrinfo
    return await self.run_in_executor(
  File "/usr/lib/python3.10/concurrent/futures/thread.py", line 58, in run
    result = self.fn(*self.args, **self.kwargs)
  File "/usr/lib/python3.10/socket.py", line 955, in getaddrinfo
    for res in _socket.getaddrinfo(host, port, family, type, proto, flags):
socket.gaierror: [Errno -3] Temporary failure in name resolution
2025-02-25 07:07:06,225 [ioloop.py:_run_callback()] - Exception in callback functools.partial(<function _HTTPConnection.__init__.<locals>.<lambda> at 0x7f09c89943a0>, <Task finished name='Task-2624064' coro=<_HTTPConnection.run() done, defined at /home/daniel/moonraker-env/lib/python3.10/site-packages/tornado/simple_httpclient.py:290> exception=gaierror(-3, 'Temporary failure in name resolution')>)
Traceback (most recent call last):
  File "/home/daniel/moonraker-env/lib/python3.10/site-packages/tornado/ioloop.py", line 750, in _run_callback
    ret = callback()
  File "/home/daniel/moonraker-env/lib/python3.10/site-packages/tornado/simple_httpclient.py", line 287, in <lambda>
    gen.convert_yielded(self.run()), lambda f: f.result()
  File "/home/daniel/moonraker-env/lib/python3.10/site-packages/tornado/simple_httpclient.py", line 340, in run
    stream = await self.tcp_client.connect(
  File "/home/daniel/moonraker-env/lib/python3.10/site-packages/tornado/tcpclient.py", line 269, in connect
    addrinfo = await self.resolver.resolve(host, port, af)
  File "/home/daniel/moonraker-env/lib/python3.10/site-packages/tornado/netutil.py", line 433, in resolve
    for fam, _, _, _, address in await asyncio.get_running_loop().getaddrinfo(
  File "/usr/lib/python3.10/asyncio/base_events.py", line 863, in getaddrinfo
    return await self.run_in_executor(
  File "/usr/lib/python3.10/concurrent/futures/thread.py", line 58, in run
    result = self.fn(*self.args, **self.kwargs)
  File "/usr/lib/python3.10/socket.py", line 955, in getaddrinfo
    for res in _socket.getaddrinfo(host, port, family, type, proto, flags):
socket.gaierror: [Errno -3] Temporary failure in name resolution
2025-02-25 07:07:12,370 [ioloop.py:_run_callback()] - Exception in callback functools.partial(<function _HTTPConnection.__init__.<locals>.<lambda> at 0x7f09c8948280>, <Task finished name='Task-2624091' coro=<_HTTPConnection.run() done, defined at /home/daniel/moonraker-env/lib/python3.10/site-packages/tornado/simple_httpclient.py:290> exception=gaierror(-3, 'Temporary failure in name resolution')>)
Traceback (most recent call last):
  File "/home/daniel/moonraker-env/lib/python3.10/site-packages/tornado/ioloop.py", line 750, in _run_callback
    ret = callback()
  File "/home/daniel/moonraker-env/lib/python3.10/site-packages/tornado/simple_httpclient.py", line 287, in <lambda>
    gen.convert_yielded(self.run()), lambda f: f.result()
  File "/home/daniel/moonraker-env/lib/python3.10/site-packages/tornado/simple_httpclient.py", line 340, in run
    stream = await self.tcp_client.connect(
  File "/home/daniel/moonraker-env/lib/python3.10/site-packages/tornado/tcpclient.py", line 269, in connect
    addrinfo = await self.resolver.resolve(host, port, af)
  File "/home/daniel/moonraker-env/lib/python3.10/site-packages/tornado/netutil.py", line 433, in resolve
    for fam, _, _, _, address in await asyncio.get_running_loop().getaddrinfo(
  File "/usr/lib/python3.10/asyncio/base_events.py", line 863, in getaddrinfo
    return await self.run_in_executor(
  File "/usr/lib/python3.10/concurrent/futures/thread.py", line 58, in run
    result = self.fn(*self.args, **self.kwargs)
  File "/usr/lib/python3.10/socket.py", line 955, in getaddrinfo
    for res in _socket.getaddrinfo(host, port, family, type, proto, flags):
socket.gaierror: [Errno -3] Temporary failure in name resolution
2025-02-25 07:07:17,867 [announcements.py:_fetch_moonlight()] - Failed to update subscription 'moonraker': Timeout while connecting
2025-02-25 07:07:18,514 [ioloop.py:_run_callback()] - Exception in callback functools.partial(<function _HTTPConnection.__init__.<locals>.<lambda> at 0x7f09c8948790>, <Task finished name='Task-2624110' coro=<_HTTPConnection.run() done, defined at /home/daniel/moonraker-env/lib/python3.10/site-packages/tornado/simple_httpclient.py:290> exception=gaierror(-3, 'Temporary failure in name resolution')>)
Traceback (most recent call last):
  File "/home/daniel/moonraker-env/lib/python3.10/site-packages/tornado/ioloop.py", line 750, in _run_callback
    ret = callback()
  File "/home/daniel/moonraker-env/lib/python3.10/site-packages/tornado/simple_httpclient.py", line 287, in <lambda>
    gen.convert_yielded(self.run()), lambda f: f.result()
  File "/home/daniel/moonraker-env/lib/python3.10/site-packages/tornado/simple_httpclient.py", line 340, in run
    stream = await self.tcp_client.connect(
  File "/home/daniel/moonraker-env/lib/python3.10/site-packages/tornado/tcpclient.py", line 269, in connect
    addrinfo = await self.resolver.resolve(host, port, af)
  File "/home/daniel/moonraker-env/lib/python3.10/site-packages/tornado/netutil.py", line 433, in resolve
    for fam, _, _, _, address in await asyncio.get_running_loop().getaddrinfo(
  File "/usr/lib/python3.10/asyncio/base_events.py", line 863, in getaddrinfo
    return await self.run_in_executor(
  File "/usr/lib/python3.10/concurrent/futures/thread.py", line 58, in run
    result = self.fn(*self.args, **self.kwargs)
  File "/usr/lib/python3.10/socket.py", line 955, in getaddrinfo
    for res in _socket.getaddrinfo(host, port, family, type, proto, flags):
socket.gaierror: [Errno -3] Temporary failure in name resolution
2025-02-25 07:07:24,658 [ioloop.py:_run_callback()] - Exception in callback functools.partial(<function _HTTPConnection.__init__.<locals>.<lambda> at 0x7f09c89489d0>, <Task finished name='Task-2624137' coro=<_HTTPConnection.run() done, defined at /home/daniel/moonraker-env/lib/python3.10/site-packages/tornado/simple_httpclient.py:290> exception=gaierror(-3, 'Temporary failure in name resolution')>)
Traceback (most recent call last):
  File "/home/daniel/moonraker-env/lib/python3.10/site-packages/tornado/ioloop.py", line 750, in _run_callback
    ret = callback()
  File "/home/daniel/moonraker-env/lib/python3.10/site-packages/tornado/simple_httpclient.py", line 287, in <lambda>
    gen.convert_yielded(self.run()), lambda f: f.result()
  File "/home/daniel/moonraker-env/lib/python3.10/site-packages/tornado/simple_httpclient.py", line 340, in run
    stream = await self.tcp_client.connect(
  File "/home/daniel/moonraker-env/lib/python3.10/site-packages/tornado/tcpclient.py", line 269, in connect
    addrinfo = await self.resolver.resolve(host, port, af)
  File "/home/daniel/moonraker-env/lib/python3.10/site-packages/tornado/netutil.py", line 433, in resolve
    for fam, _, _, _, address in await asyncio.get_running_loop().getaddrinfo(
  File "/usr/lib/python3.10/asyncio/base_events.py", line 863, in getaddrinfo
    return await self.run_in_executor(
  File "/usr/lib/python3.10/concurrent/futures/thread.py", line 58, in run
    result = self.fn(*self.args, **self.kwargs)
  File "/usr/lib/python3.10/socket.py", line 955, in getaddrinfo
    for res in _socket.getaddrinfo(host, port, family, type, proto, flags):
socket.gaierror: [Errno -3] Temporary failure in name resolution
2025-02-25 07:07:27,730 [ioloop.py:_run_callback()] - Exception in callback functools.partial(<function _HTTPConnection.__init__.<locals>.<lambda> at 0x7f09c8994820>, <Task finished name='Task-2624155' coro=<_HTTPConnection.run() done, defined at /home/daniel/moonraker-env/lib/python3.10/site-packages/tornado/simple_httpclient.py:290> exception=gaierror(-3, 'Temporary failure in name resolution')>)
Traceback (most recent call last):
  File "/home/daniel/moonraker-env/lib/python3.10/site-packages/tornado/ioloop.py", line 750, in _run_callback
    ret = callback()
  File "/home/daniel/moonraker-env/lib/python3.10/site-packages/tornado/simple_httpclient.py", line 287, in <lambda>
    gen.convert_yielded(self.run()), lambda f: f.result()
  File "/home/daniel/moonraker-env/lib/python3.10/site-packages/tornado/simple_httpclient.py", line 340, in run
    stream = await self.tcp_client.connect(
  File "/home/daniel/moonraker-env/lib/python3.10/site-packages/tornado/tcpclient.py", line 269, in connect
    addrinfo = await self.resolver.resolve(host, port, af)
  File "/home/daniel/moonraker-env/lib/python3.10/site-packages/tornado/netutil.py", line 433, in resolve
    for fam, _, _, _, address in await asyncio.get_running_loop().getaddrinfo(
  File "/usr/lib/python3.10/asyncio/base_events.py", line 863, in getaddrinfo
    return await self.run_in_executor(
  File "/usr/lib/python3.10/concurrent/futures/thread.py", line 58, in run
    result = self.fn(*self.args, **self.kwargs)
  File "/usr/lib/python3.10/socket.py", line 955, in getaddrinfo
    for res in _socket.getaddrinfo(host, port, family, type, proto, flags):
socket.gaierror: [Errno -3] Temporary failure in name resolution
2025-02-25 07:07:33,873 [ioloop.py:_run_callback()] - Exception in callback functools.partial(<function _HTTPConnection.__init__.<locals>.<lambda> at 0x7f09c8948550>, <Task finished name='Task-2624179' coro=<_HTTPConnection.run() done, defined at /home/daniel/moonraker-env/lib/python3.10/site-packages/tornado/simple_httpclient.py:290> exception=gaierror(-3, 'Temporary failure in name resolution')>)
Traceback (most recent call last):
  File "/home/daniel/moonraker-env/lib/python3.10/site-packages/tornado/ioloop.py", line 750, in _run_callback
    ret = callback()
  File "/home/daniel/moonraker-env/lib/python3.10/site-packages/tornado/simple_httpclient.py", line 287, in <lambda>
    gen.convert_yielded(self.run()), lambda f: f.result()
  File "/home/daniel/moonraker-env/lib/python3.10/site-packages/tornado/simple_httpclient.py", line 340, in run
    stream = await self.tcp_client.connect(
  File "/home/daniel/moonraker-env/lib/python3.10/site-packages/tornado/tcpclient.py", line 269, in connect
    addrinfo = await self.resolver.resolve(host, port, af)
  File "/home/daniel/moonraker-env/lib/python3.10/site-packages/tornado/netutil.py", line 433, in resolve
    for fam, _, _, _, address in await asyncio.get_running_loop().getaddrinfo(
  File "/usr/lib/python3.10/asyncio/base_events.py", line 863, in getaddrinfo
    return await self.run_in_executor(
  File "/usr/lib/python3.10/concurrent/futures/thread.py", line 58, in run
    result = self.fn(*self.args, **self.kwargs)
  File "/usr/lib/python3.10/socket.py", line 955, in getaddrinfo
    for res in _socket.getaddrinfo(host, port, family, type, proto, flags):
socket.gaierror: [Errno -3] Temporary failure in name resolution
2025-02-25 07:07:40,018 [ioloop.py:_run_callback()] - Exception in callback functools.partial(<function _HTTPConnection.__init__.<locals>.<lambda> at 0x7f09c8948160>, <Task finished name='Task-2624201' coro=<_HTTPConnection.run() done, defined at /home/daniel/moonraker-env/lib/python3.10/site-packages/tornado/simple_httpclient.py:290> exception=gaierror(-3, 'Temporary failure in name resolution')>)
Traceback (most recent call last):
  File "/home/daniel/moonraker-env/lib/python3.10/site-packages/tornado/ioloop.py", line 750, in _run_callback
    ret = callback()
  File "/home/daniel/moonraker-env/lib/python3.10/site-packages/tornado/simple_httpclient.py", line 287, in <lambda>
    gen.convert_yielded(self.run()), lambda f: f.result()
  File "/home/daniel/moonraker-env/lib/python3.10/site-packages/tornado/simple_httpclient.py", line 340, in run
    stream = await self.tcp_client.connect(
  File "/home/daniel/moonraker-env/lib/python3.10/site-packages/tornado/tcpclient.py", line 269, in connect
    addrinfo = await self.resolver.resolve(host, port, af)
  File "/home/daniel/moonraker-env/lib/python3.10/site-packages/tornado/netutil.py", line 433, in resolve
    for fam, _, _, _, address in await asyncio.get_running_loop().getaddrinfo(
  File "/usr/lib/python3.10/asyncio/base_events.py", line 863, in getaddrinfo
    return await self.run_in_executor(
  File "/usr/lib/python3.10/concurrent/futures/thread.py", line 58, in run
    result = self.fn(*self.args, **self.kwargs)
  File "/usr/lib/python3.10/socket.py", line 955, in getaddrinfo
    for res in _socket.getaddrinfo(host, port, family, type, proto, flags):
socket.gaierror: [Errno -3] Temporary failure in name resolution
2025-02-25 07:07:44,879 [announcements.py:_fetch_moonlight()] - Failed to update subscription 'klipper': Timeout while connecting
2025-02-25 07:07:46,162 [ioloop.py:_run_callback()] - Exception in callback functools.partial(<function _HTTPConnection.__init__.<locals>.<lambda> at 0x7f09c89483a0>, <Task finished name='Task-2624224' coro=<_HTTPConnection.run() done, defined at /home/daniel/moonraker-env/lib/python3.10/site-packages/tornado/simple_httpclient.py:290> exception=gaierror(-3, 'Temporary failure in name resolution')>)
Traceback (most recent call last):
  File "/home/daniel/moonraker-env/lib/python3.10/site-packages/tornado/ioloop.py", line 750, in _run_callback
    ret = callback()
  File "/home/daniel/moonraker-env/lib/python3.10/site-packages/tornado/simple_httpclient.py", line 287, in <lambda>
    gen.convert_yielded(self.run()), lambda f: f.result()
  File "/home/daniel/moonraker-env/lib/python3.10/site-packages/tornado/simple_httpclient.py", line 340, in run
    stream = await self.tcp_client.connect(
  File "/home/daniel/moonraker-env/lib/python3.10/site-packages/tornado/tcpclient.py", line 269, in connect
    addrinfo = await self.resolver.resolve(host, port, af)
  File "/home/daniel/moonraker-env/lib/python3.10/site-packages/tornado/netutil.py", line 433, in resolve
    for fam, _, _, _, address in await asyncio.get_running_loop().getaddrinfo(
  File "/usr/lib/python3.10/asyncio/base_events.py", line 863, in getaddrinfo
    return await self.run_in_executor(
  File "/usr/lib/python3.10/concurrent/futures/thread.py", line 58, in run
    result = self.fn(*self.args, **self.kwargs)
  File "/usr/lib/python3.10/socket.py", line 955, in getaddrinfo
    for res in _socket.getaddrinfo(host, port, family, type, proto, flags):
socket.gaierror: [Errno -3] Temporary failure in name resolution
2025-02-25 07:07:49,233 [ioloop.py:_run_callback()] - Exception in callback functools.partial(<function _HTTPConnection.__init__.<locals>.<lambda> at 0x7f09c8994550>, <Task finished name='Task-2624251' coro=<_HTTPConnection.run() done, defined at /home/daniel/moonraker-env/lib/python3.10/site-packages/tornado/simple_httpclient.py:290> exception=gaierror(-3, 'Temporary failure in name resolution')>)
Traceback (most recent call last):
  File "/home/daniel/moonraker-env/lib/python3.10/site-packages/tornado/ioloop.py", line 750, in _run_callback
    ret = callback()
  File "/home/daniel/moonraker-env/lib/python3.10/site-packages/tornado/simple_httpclient.py", line 287, in <lambda>
    gen.convert_yielded(self.run()), lambda f: f.result()
  File "/home/daniel/moonraker-env/lib/python3.10/site-packages/tornado/simple_httpclient.py", line 340, in run
    stream = await self.tcp_client.connect(
  File "/home/daniel/moonraker-env/lib/python3.10/site-packages/tornado/tcpclient.py", line 269, in connect
    addrinfo = await self.resolver.resolve(host, port, af)
  File "/home/daniel/moonraker-env/lib/python3.10/site-packages/tornado/netutil.py", line 433, in resolve
    for fam, _, _, _, address in await asyncio.get_running_loop().getaddrinfo(
  File "/usr/lib/python3.10/asyncio/base_events.py", line 863, in getaddrinfo
    return await self.run_in_executor(
  File "/usr/lib/python3.10/concurrent/futures/thread.py", line 58, in run
    result = self.fn(*self.args, **self.kwargs)
  File "/usr/lib/python3.10/socket.py", line 955, in getaddrinfo
    for res in _socket.getaddrinfo(host, port, family, type, proto, flags):
socket.gaierror: [Errno -3] Temporary failure in name resolution
2025-02-25 07:37:03,154 [ioloop.py:_run_callback()] - Exception in callback functools.partial(<function _HTTPConnection.__init__.<locals>.<lambda> at 0x7f09c8948700>, <Task finished name='Task-2631247' coro=<_HTTPConnection.run() done, defined at /home/daniel/moonraker-env/lib/python3.10/site-packages/tornado/simple_httpclient.py:290> exception=gaierror(-3, 'Temporary failure in name resolution')>)
Traceback (most recent call last):
  File "/home/daniel/moonraker-env/lib/python3.10/site-packages/tornado/ioloop.py", line 750, in _run_callback
    ret = callback()
  File "/home/daniel/moonraker-env/lib/python3.10/site-packages/tornado/simple_httpclient.py", line 287, in <lambda>
    gen.convert_yielded(self.run()), lambda f: f.result()
  File "/home/daniel/moonraker-env/lib/python3.10/site-packages/tornado/simple_httpclient.py", line 340, in run
    stream = await self.tcp_client.connect(
  File "/home/daniel/moonraker-env/lib/python3.10/site-packages/tornado/tcpclient.py", line 269, in connect
    addrinfo = await self.resolver.resolve(host, port, af)
  File "/home/daniel/moonraker-env/lib/python3.10/site-packages/tornado/netutil.py", line 433, in resolve
    for fam, _, _, _, address in await asyncio.get_running_loop().getaddrinfo(
  File "/usr/lib/python3.10/asyncio/base_events.py", line 863, in getaddrinfo
    return await self.run_in_executor(
  File "/usr/lib/python3.10/concurrent/futures/thread.py", line 58, in run
    result = self.fn(*self.args, **self.kwargs)
  File "/usr/lib/python3.10/socket.py", line 955, in getaddrinfo
    for res in _socket.getaddrinfo(host, port, family, type, proto, flags):
socket.gaierror: [Errno -3] Temporary failure in name resolution
2025-02-25 07:37:06,225 [ioloop.py:_run_callback()] - Exception in callback functools.partial(<function _HTTPConnection.__init__.<locals>.<lambda> at 0x7f09c89941f0>, <Task finished name='Task-2631275' coro=<_HTTPConnection.run() done, defined at /home/daniel/moonraker-env/lib/python3.10/site-packages/tornado/simple_httpclient.py:290> exception=gaierror(-3, 'Temporary failure in name resolution')>)
Traceback (most recent call last):
  File "/home/daniel/moonraker-env/lib/python3.10/site-packages/tornado/ioloop.py", line 750, in _run_callback
    ret = callback()
  File "/home/daniel/moonraker-env/lib/python3.10/site-packages/tornado/simple_httpclient.py", line 287, in <lambda>
    gen.convert_yielded(self.run()), lambda f: f.result()
  File "/home/daniel/moonraker-env/lib/python3.10/site-packages/tornado/simple_httpclient.py", line 340, in run
    stream = await self.tcp_client.connect(
  File "/home/daniel/moonraker-env/lib/python3.10/site-packages/tornado/tcpclient.py", line 269, in connect
    addrinfo = await self.resolver.resolve(host, port, af)
  File "/home/daniel/moonraker-env/lib/python3.10/site-packages/tornado/netutil.py", line 433, in resolve
    for fam, _, _, _, address in await asyncio.get_running_loop().getaddrinfo(
  File "/usr/lib/python3.10/asyncio/base_events.py", line 863, in getaddrinfo
    return await self.run_in_executor(
  File "/usr/lib/python3.10/concurrent/futures/thread.py", line 58, in run
    result = self.fn(*self.args, **self.kwargs)
  File "/usr/lib/python3.10/socket.py", line 955, in getaddrinfo
    for res in _socket.getaddrinfo(host, port, family, type, proto, flags):
socket.gaierror: [Errno -3] Temporary failure in name resolution
2025-02-25 07:37:12,369 [ioloop.py:_run_callback()] - Exception in callback functools.partial(<function _HTTPConnection.__init__.<locals>.<lambda> at 0x7f09c8994940>, <Task finished name='Task-2631293' coro=<_HTTPConnection.run() done, defined at /home/daniel/moonraker-env/lib/python3.10/site-packages/tornado/simple_httpclient.py:290> exception=gaierror(-3, 'Temporary failure in name resolution')>)
Traceback (most recent call last):
  File "/home/daniel/moonraker-env/lib/python3.10/site-packages/tornado/ioloop.py", line 750, in _run_callback
    ret = callback()
  File "/home/daniel/moonraker-env/lib/python3.10/site-packages/tornado/simple_httpclient.py", line 287, in <lambda>
    gen.convert_yielded(self.run()), lambda f: f.result()
  File "/home/daniel/moonraker-env/lib/python3.10/site-packages/tornado/simple_httpclient.py", line 340, in run
    stream = await self.tcp_client.connect(
  File "/home/daniel/moonraker-env/lib/python3.10/site-packages/tornado/tcpclient.py", line 269, in connect
    addrinfo = await self.resolver.resolve(host, port, af)
  File "/home/daniel/moonraker-env/lib/python3.10/site-packages/tornado/netutil.py", line 433, in resolve
    for fam, _, _, _, address in await asyncio.get_running_loop().getaddrinfo(
  File "/usr/lib/python3.10/asyncio/base_events.py", line 863, in getaddrinfo
    return await self.run_in_executor(
  File "/usr/lib/python3.10/concurrent/futures/thread.py", line 58, in run
    result = self.fn(*self.args, **self.kwargs)
  File "/usr/lib/python3.10/socket.py", line 955, in getaddrinfo
    for res in _socket.getaddrinfo(host, port, family, type, proto, flags):
socket.gaierror: [Errno -3] Temporary failure in name resolution
2025-02-25 07:37:17,869 [announcements.py:_fetch_moonlight()] - Failed to update subscription 'moonraker': Timeout while connecting
2025-02-25 07:37:18,514 [ioloop.py:_run_callback()] - Exception in callback functools.partial(<function _HTTPConnection.__init__.<locals>.<lambda> at 0x7f09c89488b0>, <Task finished name='Task-2631320' coro=<_HTTPConnection.run() done, defined at /home/daniel/moonraker-env/lib/python3.10/site-packages/tornado/simple_httpclient.py:290> exception=gaierror(-3, 'Temporary failure in name resolution')>)
Traceback (most recent call last):
  File "/home/daniel/moonraker-env/lib/python3.10/site-packages/tornado/ioloop.py", line 750, in _run_callback
    ret = callback()
  File "/home/daniel/moonraker-env/lib/python3.10/site-packages/tornado/simple_httpclient.py", line 287, in <lambda>
    gen.convert_yielded(self.run()), lambda f: f.result()
  File "/home/daniel/moonraker-env/lib/python3.10/site-packages/tornado/simple_httpclient.py", line 340, in run
    stream = await self.tcp_client.connect(
  File "/home/daniel/moonraker-env/lib/python3.10/site-packages/tornado/tcpclient.py", line 269, in connect
    addrinfo = await self.resolver.resolve(host, port, af)
  File "/home/daniel/moonraker-env/lib/python3.10/site-packages/tornado/netutil.py", line 433, in resolve
    for fam, _, _, _, address in await asyncio.get_running_loop().getaddrinfo(
  File "/usr/lib/python3.10/asyncio/base_events.py", line 863, in getaddrinfo
    return await self.run_in_executor(
  File "/usr/lib/python3.10/concurrent/futures/thread.py", line 58, in run
    result = self.fn(*self.args, **self.kwargs)
  File "/usr/lib/python3.10/socket.py", line 955, in getaddrinfo
    for res in _socket.getaddrinfo(host, port, family, type, proto, flags):
socket.gaierror: [Errno -3] Temporary failure in name resolution
2025-02-25 07:37:24,657 [ioloop.py:_run_callback()] - Exception in callback functools.partial(<function _HTTPConnection.__init__.<locals>.<lambda> at 0x7f09c8994040>, <Task finished name='Task-2631344' coro=<_HTTPConnection.run() done, defined at /home/daniel/moonraker-env/lib/python3.10/site-packages/tornado/simple_httpclient.py:290> exception=gaierror(-3, 'Temporary failure in name resolution')>)
Traceback (most recent call last):
  File "/home/daniel/moonraker-env/lib/python3.10/site-packages/tornado/ioloop.py", line 750, in _run_callback
    ret = callback()
  File "/home/daniel/moonraker-env/lib/python3.10/site-packages/tornado/simple_httpclient.py", line 287, in <lambda>
    gen.convert_yielded(self.run()), lambda f: f.result()
  File "/home/daniel/moonraker-env/lib/python3.10/site-packages/tornado/simple_httpclient.py", line 340, in run
    stream = await self.tcp_client.connect(
  File "/home/daniel/moonraker-env/lib/python3.10/site-packages/tornado/tcpclient.py", line 269, in connect
    addrinfo = await self.resolver.resolve(host, port, af)
  File "/home/daniel/moonraker-env/lib/python3.10/site-packages/tornado/netutil.py", line 433, in resolve
    for fam, _, _, _, address in await asyncio.get_running_loop().getaddrinfo(
  File "/usr/lib/python3.10/asyncio/base_events.py", line 863, in getaddrinfo
    return await self.run_in_executor(
  File "/usr/lib/python3.10/concurrent/futures/thread.py", line 58, in run
    result = self.fn(*self.args, **self.kwargs)
  File "/usr/lib/python3.10/socket.py", line 955, in getaddrinfo
    for res in _socket.getaddrinfo(host, port, family, type, proto, flags):
socket.gaierror: [Errno -3] Temporary failure in name resolution
2025-02-25 07:37:27,730 [ioloop.py:_run_callback()] - Exception in callback functools.partial(<function _HTTPConnection.__init__.<locals>.<lambda> at 0x7f09c89944c0>, <Task finished name='Task-2631362' coro=<_HTTPConnection.run() done, defined at /home/daniel/moonraker-env/lib/python3.10/site-packages/tornado/simple_httpclient.py:290> exception=gaierror(-3, 'Temporary failure in name resolution')>)
Traceback (most recent call last):
  File "/home/daniel/moonraker-env/lib/python3.10/site-packages/tornado/ioloop.py", line 750, in _run_callback
    ret = callback()
  File "/home/daniel/moonraker-env/lib/python3.10/site-packages/tornado/simple_httpclient.py", line 287, in <lambda>
    gen.convert_yielded(self.run()), lambda f: f.result()
  File "/home/daniel/moonraker-env/lib/python3.10/site-packages/tornado/simple_httpclient.py", line 340, in run
    stream = await self.tcp_client.connect(
  File "/home/daniel/moonraker-env/lib/python3.10/site-packages/tornado/tcpclient.py", line 269, in connect
    addrinfo = await self.resolver.resolve(host, port, af)
  File "/home/daniel/moonraker-env/lib/python3.10/site-packages/tornado/netutil.py", line 433, in resolve
    for fam, _, _, _, address in await asyncio.get_running_loop().getaddrinfo(
  File "/usr/lib/python3.10/asyncio/base_events.py", line 863, in getaddrinfo
    return await self.run_in_executor(
  File "/usr/lib/python3.10/concurrent/futures/thread.py", line 58, in run
    result = self.fn(*self.args, **self.kwargs)
  File "/usr/lib/python3.10/socket.py", line 955, in getaddrinfo
    for res in _socket.getaddrinfo(host, port, family, type, proto, flags):
socket.gaierror: [Errno -3] Temporary failure in name resolution
2025-02-25 07:37:33,873 [ioloop.py:_run_callback()] - Exception in callback functools.partial(<function _HTTPConnection.__init__.<locals>.<lambda> at 0x7f09c8948940>, <Task finished name='Task-2631389' coro=<_HTTPConnection.run() done, defined at /home/daniel/moonraker-env/lib/python3.10/site-packages/tornado/simple_httpclient.py:290> exception=gaierror(-3, 'Temporary failure in name resolution')>)
Traceback (most recent call last):
  File "/home/daniel/moonraker-env/lib/python3.10/site-packages/tornado/ioloop.py", line 750, in _run_callback
    ret = callback()
  File "/home/daniel/moonraker-env/lib/python3.10/site-packages/tornado/simple_httpclient.py", line 287, in <lambda>
    gen.convert_yielded(self.run()), lambda f: f.result()
  File "/home/daniel/moonraker-env/lib/python3.10/site-packages/tornado/simple_httpclient.py", line 340, in run
    stream = await self.tcp_client.connect(
  File "/home/daniel/moonraker-env/lib/python3.10/site-packages/tornado/tcpclient.py", line 269, in connect
    addrinfo = await self.resolver.resolve(host, port, af)
  File "/home/daniel/moonraker-env/lib/python3.10/site-packages/tornado/netutil.py", line 433, in resolve
    for fam, _, _, _, address in await asyncio.get_running_loop().getaddrinfo(
  File "/usr/lib/python3.10/asyncio/base_events.py", line 863, in getaddrinfo
    return await self.run_in_executor(
  File "/usr/lib/python3.10/concurrent/futures/thread.py", line 58, in run
    result = self.fn(*self.args, **self.kwargs)
  File "/usr/lib/python3.10/socket.py", line 955, in getaddrinfo
    for res in _socket.getaddrinfo(host, port, family, type, proto, flags):
socket.gaierror: [Errno -3] Temporary failure in name resolution
2025-02-25 07:37:40,018 [ioloop.py:_run_callback()] - Exception in callback functools.partial(<function _HTTPConnection.__init__.<locals>.<lambda> at 0x7f09c8994b80>, <Task finished name='Task-2631408' coro=<_HTTPConnection.run() done, defined at /home/daniel/moonraker-env/lib/python3.10/site-packages/tornado/simple_httpclient.py:290> exception=gaierror(-3, 'Temporary failure in name resolution')>)
Traceback (most recent call last):
  File "/home/daniel/moonraker-env/lib/python3.10/site-packages/tornado/ioloop.py", line 750, in _run_callback
    ret = callback()
  File "/home/daniel/moonraker-env/lib/python3.10/site-packages/tornado/simple_httpclient.py", line 287, in <lambda>
    gen.convert_yielded(self.run()), lambda f: f.result()
  File "/home/daniel/moonraker-env/lib/python3.10/site-packages/tornado/simple_httpclient.py", line 340, in run
    stream = await self.tcp_client.connect(
  File "/home/daniel/moonraker-env/lib/python3.10/site-packages/tornado/tcpclient.py", line 269, in connect
    addrinfo = await self.resolver.resolve(host, port, af)
  File "/home/daniel/moonraker-env/lib/python3.10/site-packages/tornado/netutil.py", line 433, in resolve
    for fam, _, _, _, address in await asyncio.get_running_loop().getaddrinfo(
  File "/usr/lib/python3.10/asyncio/base_events.py", line 863, in getaddrinfo
    return await self.run_in_executor(
  File "/usr/lib/python3.10/concurrent/futures/thread.py", line 58, in run
    result = self.fn(*self.args, **self.kwargs)
  File "/usr/lib/python3.10/socket.py", line 955, in getaddrinfo
    for res in _socket.getaddrinfo(host, port, family, type, proto, flags):
socket.gaierror: [Errno -3] Temporary failure in name resolution
2025-02-25 07:37:44,878 [announcements.py:_fetch_moonlight()] - Failed to update subscription 'klipper': Timeout while connecting
2025-02-25 07:37:46,166 [ioloop.py:_run_callback()] - Exception in callback functools.partial(<function _HTTPConnection.__init__.<locals>.<lambda> at 0x7f09c923e050>, <Task finished name='Task-2631435' coro=<_HTTPConnection.run() done, defined at /home/daniel/moonraker-env/lib/python3.10/site-packages/tornado/simple_httpclient.py:290> exception=gaierror(-3, 'Temporary failure in name resolution')>)
Traceback (most recent call last):
  File "/home/daniel/moonraker-env/lib/python3.10/site-packages/tornado/ioloop.py", line 750, in _run_callback
    ret = callback()
  File "/home/daniel/moonraker-env/lib/python3.10/site-packages/tornado/simple_httpclient.py", line 287, in <lambda>
    gen.convert_yielded(self.run()), lambda f: f.result()
  File "/home/daniel/moonraker-env/lib/python3.10/site-packages/tornado/simple_httpclient.py", line 340, in run
    stream = await self.tcp_client.connect(
  File "/home/daniel/moonraker-env/lib/python3.10/site-packages/tornado/tcpclient.py", line 269, in connect
    addrinfo = await self.resolver.resolve(host, port, af)
  File "/home/daniel/moonraker-env/lib/python3.10/site-packages/tornado/netutil.py", line 433, in resolve
    for fam, _, _, _, address in await asyncio.get_running_loop().getaddrinfo(
  File "/usr/lib/python3.10/asyncio/base_events.py", line 863, in getaddrinfo
    return await self.run_in_executor(
  File "/usr/lib/python3.10/concurrent/futures/thread.py", line 58, in run
    result = self.fn(*self.args, **self.kwargs)
  File "/usr/lib/python3.10/socket.py", line 955, in getaddrinfo
    for res in _socket.getaddrinfo(host, port, family, type, proto, flags):
socket.gaierror: [Errno -3] Temporary failure in name resolution
2025-02-25 07:37:49,234 [ioloop.py:_run_callback()] - Exception in callback functools.partial(<function _HTTPConnection.__init__.<locals>.<lambda> at 0x7f09c89945e0>, <Task finished name='Task-2631453' coro=<_HTTPConnection.run() done, defined at /home/daniel/moonraker-env/lib/python3.10/site-packages/tornado/simple_httpclient.py:290> exception=gaierror(-3, 'Temporary failure in name resolution')>)
Traceback (most recent call last):
  File "/home/daniel/moonraker-env/lib/python3.10/site-packages/tornado/ioloop.py", line 750, in _run_callback
    ret = callback()
  File "/home/daniel/moonraker-env/lib/python3.10/site-packages/tornado/simple_httpclient.py", line 287, in <lambda>
    gen.convert_yielded(self.run()), lambda f: f.result()
  File "/home/daniel/moonraker-env/lib/python3.10/site-packages/tornado/simple_httpclient.py", line 340, in run
    stream = await self.tcp_client.connect(
  File "/home/daniel/moonraker-env/lib/python3.10/site-packages/tornado/tcpclient.py", line 269, in connect
    addrinfo = await self.resolver.resolve(host, port, af)
  File "/home/daniel/moonraker-env/lib/python3.10/site-packages/tornado/netutil.py", line 433, in resolve
    for fam, _, _, _, address in await asyncio.get_running_loop().getaddrinfo(
  File "/usr/lib/python3.10/asyncio/base_events.py", line 863, in getaddrinfo
    return await self.run_in_executor(
  File "/usr/lib/python3.10/concurrent/futures/thread.py", line 58, in run
    result = self.fn(*self.args, **self.kwargs)
  File "/usr/lib/python3.10/socket.py", line 955, in getaddrinfo
    for res in _socket.getaddrinfo(host, port, family, type, proto, flags):
socket.gaierror: [Errno -3] Temporary failure in name resolution
2025-02-25 08:07:00,929 [ioloop.py:_run_callback()] - Exception in callback functools.partial(<function _HTTPConnection.__init__.<locals>.<lambda> at 0x7f09c89481f0>, <Task finished name='Task-2638457' coro=<_HTTPConnection.run() done, defined at /home/daniel/moonraker-env/lib/python3.10/site-packages/tornado/simple_httpclient.py:290> exception=gaierror(-3, 'Temporary failure in name resolution')>)
Traceback (most recent call last):
  File "/home/daniel/moonraker-env/lib/python3.10/site-packages/tornado/ioloop.py", line 750, in _run_callback
    ret = callback()
  File "/home/daniel/moonraker-env/lib/python3.10/site-packages/tornado/simple_httpclient.py", line 287, in <lambda>
    gen.convert_yielded(self.run()), lambda f: f.result()
  File "/home/daniel/moonraker-env/lib/python3.10/site-packages/tornado/simple_httpclient.py", line 340, in run
    stream = await self.tcp_client.connect(
  File "/home/daniel/moonraker-env/lib/python3.10/site-packages/tornado/tcpclient.py", line 269, in connect
    addrinfo = await self.resolver.resolve(host, port, af)
  File "/home/daniel/moonraker-env/lib/python3.10/site-packages/tornado/netutil.py", line 433, in resolve
    for fam, _, _, _, address in await asyncio.get_running_loop().getaddrinfo(
  File "/usr/lib/python3.10/asyncio/base_events.py", line 863, in getaddrinfo
    return await self.run_in_executor(
  File "/usr/lib/python3.10/concurrent/futures/thread.py", line 58, in run
    result = self.fn(*self.args, **self.kwargs)
  File "/usr/lib/python3.10/socket.py", line 955, in getaddrinfo
    for res in _socket.getaddrinfo(host, port, family, type, proto, flags):
socket.gaierror: [Errno -3] Temporary failure in name resolution
2025-02-25 08:07:02,444 [announcements.py:_fetch_moonlight()] - Failed to update subscription 'moonraker': [Errno -3] Temporary failure in name resolution
2025-02-25 08:07:04,465 [announcements.py:_fetch_moonlight()] - Failed to update subscription 'klipper': [Errno -3] Temporary failure in name resolution
2025-02-25 08:07:04,801 [machine.py:_find_public_ip()] - Detected Local IP: 192.168.0.40
2025-02-25 08:07:17,306 [power.py:init_state()] - Device Init Error: printer_plug
Traceback (most recent call last):
  File "/home/daniel/moonraker/moonraker/components/power.py", line 898, in init_state
    state: int = await self._send_info_request()
  File "/home/daniel/moonraker/moonraker/components/power.py", line 884, in _send_info_request
    res = await self._send_tplink_command("info")
  File "/home/daniel/moonraker/moonraker/components/power.py", line 839, in _send_tplink_command
    reader, writer = await asyncio.open_connection(
  File "/usr/lib/python3.10/asyncio/streams.py", line 48, in open_connection
    transport, _ = await loop.create_connection(
  File "/usr/lib/python3.10/asyncio/base_events.py", line 1076, in create_connection
    raise exceptions[0]
  File "/usr/lib/python3.10/asyncio/base_events.py", line 1060, in create_connection
    sock = await self._connect_sock(
  File "/usr/lib/python3.10/asyncio/base_events.py", line 969, in _connect_sock
    await self.sock_connect(sock, address)
  File "/usr/lib/python3.10/asyncio/selector_events.py", line 501, in sock_connect
    return await fut
  File "/usr/lib/python3.10/asyncio/selector_events.py", line 509, in _sock_connect
    sock.connect(address)
OSError: [Errno 101] Network is unreachable
2025-02-25 08:08:14,891 [machine.py:_find_public_ip()] - Detected Local IP: 192.168.0.40
2025-02-25 08:08:15,377 [power.py:init_state()] - Device Init Error: printer_plug
Traceback (most recent call last):
  File "/home/daniel/moonraker/moonraker/components/power.py", line 898, in init_state
    state: int = await self._send_info_request()
  File "/home/daniel/moonraker/moonraker/components/power.py", line 884, in _send_info_request
    res = await self._send_tplink_command("info")
  File "/home/daniel/moonraker/moonraker/components/power.py", line 839, in _send_tplink_command
    reader, writer = await asyncio.open_connection(
  File "/usr/lib/python3.10/asyncio/streams.py", line 48, in open_connection
    transport, _ = await loop.create_connection(
  File "/usr/lib/python3.10/asyncio/base_events.py", line 1076, in create_connection
    raise exceptions[0]
  File "/usr/lib/python3.10/asyncio/base_events.py", line 1060, in create_connection
    sock = await self._connect_sock(
  File "/usr/lib/python3.10/asyncio/base_events.py", line 969, in _connect_sock
    await self.sock_connect(sock, address)
  File "/usr/lib/python3.10/asyncio/selector_events.py", line 501, in sock_connect
    return await fut
  File "/usr/lib/python3.10/asyncio/selector_events.py", line 541, in _sock_connect_cb
    raise OSError(err, f'Connect call failed {address}')
OSError: [Errno 113] Connect call failed ('192.168.0.83', 9999)
