-------------------- Log Start | Wed Jan  8 13:27:03 2025 --------------------
data_path: /home/daniel/printer_data
is_default_data_path: False
config_file: /home/daniel/printer_data/config/moonraker.conf
startup_warnings: []
verbose: False
debug: False
asyncio_debug: False
is_backup_config: False
is_python_package: False
instance_uuid: b58008b63adb40a8a31f7dfdb480fcc5
unix_socket_path: /home/daniel/printer_data/comms/moonraker.sock
software_version: v0.8.0-311-g65a8271
git_branch: master
git_remote: origin
git_repo_url: https://github.com/Arksine/moonraker.git
modified_files: []
unofficial_components: []
log_file: /home/daniel/printer_data/logs/moonraker.log
python_version: 3.10.12 (main, Sep 11 2024, 15:47:36) [GCC 11.4.0]
launch_args: /home/daniel/moonraker-env/bin/python /home/daniel/moonraker/moonraker/moonraker.py -d /home/daniel/printer_data
msgspec_enabled: False
uvloop_enabled: False

#################### Moonraker Configuration ####################

[server]
host = 0.0.0.0
port = 7125
klippy_uds_address = /home/daniel/printer_data/comms/klippy.sock

[authorization]
trusted_clients = 
	10.0.0.0/8
	127.0.0.0/8
	169.254.0.0/16
	172.16.0.0/12
	192.168.0.0/16
	FE80::/10
	::1/128
cors_domains = 
	*.lan
	*.local
	*://localhost
	*://localhost:*
	*://my.mainsail.xyz
	*://app.fluidd.xyz

[octoprint_compat]

[file_manager]
enable_object_processing = True

[power printer_plug]
type = tplink_smartplug
address = 192.168.0.83

[history]

[update_manager]
channel = dev
refresh_interval = 168

[update_manager mainsail-config]
type = git_repo
primary_branch = master
path = ~/mainsail-config
origin = https://github.com/mainsail-crew/mainsail-config.git
managed_services = klipper

[update_manager mainsail]
type = web
channel = stable
repo = mainsail-crew/mainsail
path = ~/mainsail

[update_manager Klipper-Adaptive-Meshing-Purging]
type = git_repo
channel = dev
path = ~/Klipper-Adaptive-Meshing-Purging
origin = https://github.com/kyleisah/Klipper-Adaptive-Meshing-Purging.git
managed_services = klipper
primary_branch = main

[update_manager klipper-backup]
type = git_repo
path = ~/klipper-backup
origin = https://github.com/Staubgeborener/klipper-backup.git
managed_services = moonraker
primary_branch = main

[update_manager crowsnest]
type = git_repo
path = ~/crowsnest
origin = https://github.com/mainsail-crew/crowsnest.git
managed_services = crowsnest
install_script = tools/pkglist.sh

#################################################################
All Configuration Files:
/home/daniel/printer_data/config/moonraker.conf
#################################################################

Database Versions: pylmdb = 1.4.1, lmdb = (0, 9, 29)
Unsafe Shutdown Count: 4

System Info:

***python***
  version: (3, 10, 12, 'final', 0)
  version_string: 3.10.12 (main, Sep 11 2024, 15:47:36) [GCC 11.4.0]

***cpu_info***
  cpu_count: 4
  bits: 64bit
  processor: x86_64
  cpu_desc: Intel(R) Core(TM) i5-5200U CPU @ 2.20GHz
  serial_number: 
  hardware_desc: 
  model: 
  total_memory: 12115828
  memory_units: kB

***sd_info***

***distribution***
  name: Ubuntu 22.04.4 LTS
  id: ubuntu
  version: 22.04
  version_parts: {'major': '22', 'minor': '04', 'build_number': ''}
  like: debian
  codename: jammy
  release_info: {}

***virtualization***
  virt_type: none
  virt_identifier: none

***network***

***canbus***

***Allowed Services***
  klipper_mcu
  webcamd
  MoonCord
  KlipperScreen
  moonraker-telegram-bot
  moonraker-obico
  sonar
  crowsnest
  octoeverywhere
  ratos-configurator
Module libcamera unavailble, import failed

Systemd unit moonraker.service:
unit_name: moonraker.service
is_default: True
manager: systemd
Properties:
**Requires=['network-online.target', 'sysinit.target', 'system.slice', '-.mount']
**After=['network-online.target', 'systemd-journald.socket', 'sysinit.target', 'system.slice', '-.mount', 'basic.target']
**SupplementaryGroups=['moonraker-admin']
**EnvironmentFiles=/home/daniel/printer_data/systemd/moonraker.env
**ExecStart=/home/daniel/moonraker-env/bin/python $MOONRAKER_ARGS
**WorkingDirectory=/home/daniel/moonraker
**FragmentPath=/etc/systemd/system/moonraker.service
**Description=API Server for Klipper SV1
**User=daniel

Systemd unit klipper.service:
unit_name: klipper.service
is_default: True
manager: systemd
Properties:
**Requires=['-.mount', 'sysinit.target', 'system.slice']
**After=['-.mount', 'network-online.target', 'systemd-journald.socket', 'system.slice', 'sysinit.target', 'basic.target']
**SupplementaryGroups=[]
**EnvironmentFiles=/home/daniel/printer_data/systemd/klipper.env
**ExecStart=/home/daniel/klippy-env/bin/python $KLIPPER_ARGS
**WorkingDirectory=/home/daniel/klipper
**FragmentPath=/etc/systemd/system/klipper.service
**Description=Klipper 3D Printer Firmware SV1
**User=daniel
Git Repo moonraker: No warnings detected
Git Repo klipper: No warnings detected
Git Repo mainsail-config: No warnings detected
Git Repo Klipper-Adaptive-Meshing-Purging: No warnings detected
Git Repo klipper-backup: No warnings detected
Git Repo crowsnest: No warnings detected
Klipper Version: v0.12.0-111-g4f00f219
2025-01-08 08:27:03,839 [ioloop.py:_run_callback()] - Exception in callback functools.partial(<function _HTTPConnection.__init__.<locals>.<lambda> at 0x7f93d515add0>, <Task finished name='Task-129454255' coro=<_HTTPConnection.run() done, defined at /home/daniel/moonraker-env/lib/python3.10/site-packages/tornado/simple_httpclient.py:290> exception=gaierror(-3, 'Temporary failure in name resolution')>)
Traceback (most recent call last):
  File "/home/daniel/moonraker-env/lib/python3.10/site-packages/tornado/ioloop.py", line 750, in _run_callback
    ret = callback()
  File "/home/daniel/moonraker-env/lib/python3.10/site-packages/tornado/simple_httpclient.py", line 287, in <lambda>
    gen.convert_yielded(self.run()), lambda f: f.result()
  File "/home/daniel/moonraker-env/lib/python3.10/site-packages/tornado/simple_httpclient.py", line 340, in run
    stream = await self.tcp_client.connect(
  File "/home/daniel/moonraker-env/lib/python3.10/site-packages/tornado/tcpclient.py", line 269, in connect
    addrinfo = await self.resolver.resolve(host, port, af)
  File "/home/daniel/moonraker-env/lib/python3.10/site-packages/tornado/netutil.py", line 433, in resolve
    for fam, _, _, _, address in await asyncio.get_running_loop().getaddrinfo(
  File "/usr/lib/python3.10/asyncio/base_events.py", line 863, in getaddrinfo
    return await self.run_in_executor(
  File "/usr/lib/python3.10/concurrent/futures/thread.py", line 58, in run
    result = self.fn(*self.args, **self.kwargs)
  File "/usr/lib/python3.10/socket.py", line 955, in getaddrinfo
    for res in _socket.getaddrinfo(host, port, family, type, proto, flags):
socket.gaierror: [Errno -3] Temporary failure in name resolution
2025-01-08 08:27:05,115 [ioloop.py:_run_callback()] - Exception in callback functools.partial(<function _HTTPConnection.__init__.<locals>.<lambda> at 0x7f93d515a9e0>, <Task finished name='Task-129454081' coro=<_HTTPConnection.run() done, defined at /home/daniel/moonraker-env/lib/python3.10/site-packages/tornado/simple_httpclient.py:290> exception=gaierror(-3, 'Temporary failure in name resolution')>)
Traceback (most recent call last):
  File "/home/daniel/moonraker-env/lib/python3.10/site-packages/tornado/ioloop.py", line 750, in _run_callback
    ret = callback()
  File "/home/daniel/moonraker-env/lib/python3.10/site-packages/tornado/simple_httpclient.py", line 287, in <lambda>
    gen.convert_yielded(self.run()), lambda f: f.result()
  File "/home/daniel/moonraker-env/lib/python3.10/site-packages/tornado/simple_httpclient.py", line 340, in run
    stream = await self.tcp_client.connect(
  File "/home/daniel/moonraker-env/lib/python3.10/site-packages/tornado/tcpclient.py", line 269, in connect
    addrinfo = await self.resolver.resolve(host, port, af)
  File "/home/daniel/moonraker-env/lib/python3.10/site-packages/tornado/netutil.py", line 433, in resolve
    for fam, _, _, _, address in await asyncio.get_running_loop().getaddrinfo(
  File "/usr/lib/python3.10/asyncio/base_events.py", line 863, in getaddrinfo
    return await self.run_in_executor(
  File "/usr/lib/python3.10/concurrent/futures/thread.py", line 58, in run
    result = self.fn(*self.args, **self.kwargs)
  File "/usr/lib/python3.10/socket.py", line 955, in getaddrinfo
    for res in _socket.getaddrinfo(host, port, family, type, proto, flags):
socket.gaierror: [Errno -3] Temporary failure in name resolution
2025-01-08 08:27:06,910 [ioloop.py:_run_callback()] - Exception in callback functools.partial(<function _HTTPConnection.__init__.<locals>.<lambda> at 0x7f93d515beb0>, <Task finished name='Task-129454441' coro=<_HTTPConnection.run() done, defined at /home/daniel/moonraker-env/lib/python3.10/site-packages/tornado/simple_httpclient.py:290> exception=gaierror(-3, 'Temporary failure in name resolution')>)
Traceback (most recent call last):
  File "/home/daniel/moonraker-env/lib/python3.10/site-packages/tornado/ioloop.py", line 750, in _run_callback
    ret = callback()
  File "/home/daniel/moonraker-env/lib/python3.10/site-packages/tornado/simple_httpclient.py", line 287, in <lambda>
    gen.convert_yielded(self.run()), lambda f: f.result()
  File "/home/daniel/moonraker-env/lib/python3.10/site-packages/tornado/simple_httpclient.py", line 340, in run
    stream = await self.tcp_client.connect(
  File "/home/daniel/moonraker-env/lib/python3.10/site-packages/tornado/tcpclient.py", line 269, in connect
    addrinfo = await self.resolver.resolve(host, port, af)
  File "/home/daniel/moonraker-env/lib/python3.10/site-packages/tornado/netutil.py", line 433, in resolve
    for fam, _, _, _, address in await asyncio.get_running_loop().getaddrinfo(
  File "/usr/lib/python3.10/asyncio/base_events.py", line 863, in getaddrinfo
    return await self.run_in_executor(
  File "/usr/lib/python3.10/concurrent/futures/thread.py", line 58, in run
    result = self.fn(*self.args, **self.kwargs)
  File "/usr/lib/python3.10/socket.py", line 955, in getaddrinfo
    for res in _socket.getaddrinfo(host, port, family, type, proto, flags):
socket.gaierror: [Errno -3] Temporary failure in name resolution
2025-01-08 08:27:12,109 [announcements.py:_fetch_moonlight()] - Failed to update subscription 'moonraker': Timeout while connecting
2025-01-08 08:27:13,079 [ioloop.py:_run_callback()] - Exception in callback functools.partial(<function _HTTPConnection.__init__.<locals>.<lambda> at 0x7f93d515a0e0>, <Task finished name='Task-129454610' coro=<_HTTPConnection.run() done, defined at /home/daniel/moonraker-env/lib/python3.10/site-packages/tornado/simple_httpclient.py:290> exception=gaierror(-3, 'Temporary failure in name resolution')>)
Traceback (most recent call last):
  File "/home/daniel/moonraker-env/lib/python3.10/site-packages/tornado/ioloop.py", line 750, in _run_callback
    ret = callback()
  File "/home/daniel/moonraker-env/lib/python3.10/site-packages/tornado/simple_httpclient.py", line 287, in <lambda>
    gen.convert_yielded(self.run()), lambda f: f.result()
  File "/home/daniel/moonraker-env/lib/python3.10/site-packages/tornado/simple_httpclient.py", line 340, in run
    stream = await self.tcp_client.connect(
  File "/home/daniel/moonraker-env/lib/python3.10/site-packages/tornado/tcpclient.py", line 269, in connect
    addrinfo = await self.resolver.resolve(host, port, af)
  File "/home/daniel/moonraker-env/lib/python3.10/site-packages/tornado/netutil.py", line 433, in resolve
    for fam, _, _, _, address in await asyncio.get_running_loop().getaddrinfo(
  File "/usr/lib/python3.10/asyncio/base_events.py", line 863, in getaddrinfo
    return await self.run_in_executor(
  File "/usr/lib/python3.10/concurrent/futures/thread.py", line 58, in run
    result = self.fn(*self.args, **self.kwargs)
  File "/usr/lib/python3.10/socket.py", line 955, in getaddrinfo
    for res in _socket.getaddrinfo(host, port, family, type, proto, flags):
socket.gaierror: [Errno -3] Temporary failure in name resolution
2025-01-08 08:27:19,198 [ioloop.py:_run_callback()] - Exception in callback functools.partial(<function _HTTPConnection.__init__.<locals>.<lambda> at 0x7f93d515a200>, <Task finished name='Task-129454794' coro=<_HTTPConnection.run() done, defined at /home/daniel/moonraker-env/lib/python3.10/site-packages/tornado/simple_httpclient.py:290> exception=gaierror(-3, 'Temporary failure in name resolution')>)
Traceback (most recent call last):
  File "/home/daniel/moonraker-env/lib/python3.10/site-packages/tornado/ioloop.py", line 750, in _run_callback
    ret = callback()
  File "/home/daniel/moonraker-env/lib/python3.10/site-packages/tornado/simple_httpclient.py", line 287, in <lambda>
    gen.convert_yielded(self.run()), lambda f: f.result()
  File "/home/daniel/moonraker-env/lib/python3.10/site-packages/tornado/simple_httpclient.py", line 340, in run
    stream = await self.tcp_client.connect(
  File "/home/daniel/moonraker-env/lib/python3.10/site-packages/tornado/tcpclient.py", line 269, in connect
    addrinfo = await self.resolver.resolve(host, port, af)
  File "/home/daniel/moonraker-env/lib/python3.10/site-packages/tornado/netutil.py", line 433, in resolve
    for fam, _, _, _, address in await asyncio.get_running_loop().getaddrinfo(
  File "/usr/lib/python3.10/asyncio/base_events.py", line 863, in getaddrinfo
    return await self.run_in_executor(
  File "/usr/lib/python3.10/concurrent/futures/thread.py", line 58, in run
    result = self.fn(*self.args, **self.kwargs)
  File "/usr/lib/python3.10/socket.py", line 955, in getaddrinfo
    for res in _socket.getaddrinfo(host, port, family, type, proto, flags):
socket.gaierror: [Errno -3] Temporary failure in name resolution
2025-01-08 08:27:22,406 [ioloop.py:_run_callback()] - Exception in callback functools.partial(<function _HTTPConnection.__init__.<locals>.<lambda> at 0x7f93d515a950>, <Task finished name='Task-129454952' coro=<_HTTPConnection.run() done, defined at /home/daniel/moonraker-env/lib/python3.10/site-packages/tornado/simple_httpclient.py:290> exception=gaierror(-3, 'Temporary failure in name resolution')>)
Traceback (most recent call last):
  File "/home/daniel/moonraker-env/lib/python3.10/site-packages/tornado/ioloop.py", line 750, in _run_callback
    ret = callback()
  File "/home/daniel/moonraker-env/lib/python3.10/site-packages/tornado/simple_httpclient.py", line 287, in <lambda>
    gen.convert_yielded(self.run()), lambda f: f.result()
  File "/home/daniel/moonraker-env/lib/python3.10/site-packages/tornado/simple_httpclient.py", line 340, in run
    stream = await self.tcp_client.connect(
  File "/home/daniel/moonraker-env/lib/python3.10/site-packages/tornado/tcpclient.py", line 269, in connect
    addrinfo = await self.resolver.resolve(host, port, af)
  File "/home/daniel/moonraker-env/lib/python3.10/site-packages/tornado/netutil.py", line 433, in resolve
    for fam, _, _, _, address in await asyncio.get_running_loop().getaddrinfo(
  File "/usr/lib/python3.10/asyncio/base_events.py", line 863, in getaddrinfo
    return await self.run_in_executor(
  File "/usr/lib/python3.10/concurrent/futures/thread.py", line 58, in run
    result = self.fn(*self.args, **self.kwargs)
  File "/usr/lib/python3.10/socket.py", line 955, in getaddrinfo
    for res in _socket.getaddrinfo(host, port, family, type, proto, flags):
socket.gaierror: [Errno -3] Temporary failure in name resolution
2025-01-08 08:27:37,623 [ioloop.py:_run_callback()] - Exception in callback functools.partial(<function _HTTPConnection.__init__.<locals>.<lambda> at 0x7f93d515bbe0>, <Task finished name='Task-129455128' coro=<_HTTPConnection.run() done, defined at /home/daniel/moonraker-env/lib/python3.10/site-packages/tornado/simple_httpclient.py:290> exception=gaierror(-3, 'Temporary failure in name resolution')>)
Traceback (most recent call last):
  File "/home/daniel/moonraker-env/lib/python3.10/site-packages/tornado/ioloop.py", line 750, in _run_callback
    ret = callback()
  File "/home/daniel/moonraker-env/lib/python3.10/site-packages/tornado/simple_httpclient.py", line 287, in <lambda>
    gen.convert_yielded(self.run()), lambda f: f.result()
  File "/home/daniel/moonraker-env/lib/python3.10/site-packages/tornado/simple_httpclient.py", line 340, in run
    stream = await self.tcp_client.connect(
  File "/home/daniel/moonraker-env/lib/python3.10/site-packages/tornado/tcpclient.py", line 269, in connect
    addrinfo = await self.resolver.resolve(host, port, af)
  File "/home/daniel/moonraker-env/lib/python3.10/site-packages/tornado/netutil.py", line 433, in resolve
    for fam, _, _, _, address in await asyncio.get_running_loop().getaddrinfo(
  File "/usr/lib/python3.10/asyncio/base_events.py", line 863, in getaddrinfo
    return await self.run_in_executor(
  File "/usr/lib/python3.10/concurrent/futures/thread.py", line 58, in run
    result = self.fn(*self.args, **self.kwargs)
  File "/usr/lib/python3.10/socket.py", line 955, in getaddrinfo
    for res in _socket.getaddrinfo(host, port, family, type, proto, flags):
socket.gaierror: [Errno -3] Temporary failure in name resolution
2025-01-08 08:27:39,116 [announcements.py:_fetch_moonlight()] - Failed to update subscription 'klipper': Timeout while connecting
2025-01-08 08:27:40,833 [ioloop.py:_run_callback()] - Exception in callback functools.partial(<function _HTTPConnection.__init__.<locals>.<lambda> at 0x7f93d515aa70>, <Task finished name='Task-129455304' coro=<_HTTPConnection.run() done, defined at /home/daniel/moonraker-env/lib/python3.10/site-packages/tornado/simple_httpclient.py:290> exception=gaierror(-3, 'Temporary failure in name resolution')>)
Traceback (most recent call last):
  File "/home/daniel/moonraker-env/lib/python3.10/site-packages/tornado/ioloop.py", line 750, in _run_callback
    ret = callback()
  File "/home/daniel/moonraker-env/lib/python3.10/site-packages/tornado/simple_httpclient.py", line 287, in <lambda>
    gen.convert_yielded(self.run()), lambda f: f.result()
  File "/home/daniel/moonraker-env/lib/python3.10/site-packages/tornado/simple_httpclient.py", line 340, in run
    stream = await self.tcp_client.connect(
  File "/home/daniel/moonraker-env/lib/python3.10/site-packages/tornado/tcpclient.py", line 269, in connect
    addrinfo = await self.resolver.resolve(host, port, af)
  File "/home/daniel/moonraker-env/lib/python3.10/site-packages/tornado/netutil.py", line 433, in resolve
    for fam, _, _, _, address in await asyncio.get_running_loop().getaddrinfo(
  File "/usr/lib/python3.10/asyncio/base_events.py", line 863, in getaddrinfo
    return await self.run_in_executor(
  File "/usr/lib/python3.10/concurrent/futures/thread.py", line 58, in run
    result = self.fn(*self.args, **self.kwargs)
  File "/usr/lib/python3.10/socket.py", line 955, in getaddrinfo
    for res in _socket.getaddrinfo(host, port, family, type, proto, flags):
socket.gaierror: [Errno -3] Temporary failure in name resolution
2025-01-08 08:27:43,808 [ioloop.py:_run_callback()] - Exception in callback functools.partial(<function _HTTPConnection.__init__.<locals>.<lambda> at 0x7f93d515bf40>, <Task finished name='Task-129455480' coro=<_HTTPConnection.run() done, defined at /home/daniel/moonraker-env/lib/python3.10/site-packages/tornado/simple_httpclient.py:290> exception=gaierror(-3, 'Temporary failure in name resolution')>)
Traceback (most recent call last):
  File "/home/daniel/moonraker-env/lib/python3.10/site-packages/tornado/ioloop.py", line 750, in _run_callback
    ret = callback()
  File "/home/daniel/moonraker-env/lib/python3.10/site-packages/tornado/simple_httpclient.py", line 287, in <lambda>
    gen.convert_yielded(self.run()), lambda f: f.result()
  File "/home/daniel/moonraker-env/lib/python3.10/site-packages/tornado/simple_httpclient.py", line 340, in run
    stream = await self.tcp_client.connect(
  File "/home/daniel/moonraker-env/lib/python3.10/site-packages/tornado/tcpclient.py", line 269, in connect
    addrinfo = await self.resolver.resolve(host, port, af)
  File "/home/daniel/moonraker-env/lib/python3.10/site-packages/tornado/netutil.py", line 433, in resolve
    for fam, _, _, _, address in await asyncio.get_running_loop().getaddrinfo(
  File "/usr/lib/python3.10/asyncio/base_events.py", line 863, in getaddrinfo
    return await self.run_in_executor(
  File "/usr/lib/python3.10/concurrent/futures/thread.py", line 58, in run
    result = self.fn(*self.args, **self.kwargs)
  File "/usr/lib/python3.10/socket.py", line 955, in getaddrinfo
    for res in _socket.getaddrinfo(host, port, family, type, proto, flags):
socket.gaierror: [Errno -3] Temporary failure in name resolution
2025-01-08 08:27:47,085 [ioloop.py:_run_callback()] - Exception in callback functools.partial(<function _HTTPConnection.__init__.<locals>.<lambda> at 0x7f93d696cdc0>, <Task finished name='Task-129455665' coro=<_HTTPConnection.run() done, defined at /home/daniel/moonraker-env/lib/python3.10/site-packages/tornado/simple_httpclient.py:290> exception=gaierror(-3, 'Temporary failure in name resolution')>)
Traceback (most recent call last):
  File "/home/daniel/moonraker-env/lib/python3.10/site-packages/tornado/ioloop.py", line 750, in _run_callback
    ret = callback()
  File "/home/daniel/moonraker-env/lib/python3.10/site-packages/tornado/simple_httpclient.py", line 287, in <lambda>
    gen.convert_yielded(self.run()), lambda f: f.result()
  File "/home/daniel/moonraker-env/lib/python3.10/site-packages/tornado/simple_httpclient.py", line 340, in run
    stream = await self.tcp_client.connect(
  File "/home/daniel/moonraker-env/lib/python3.10/site-packages/tornado/tcpclient.py", line 269, in connect
    addrinfo = await self.resolver.resolve(host, port, af)
  File "/home/daniel/moonraker-env/lib/python3.10/site-packages/tornado/netutil.py", line 433, in resolve
    for fam, _, _, _, address in await asyncio.get_running_loop().getaddrinfo(
  File "/usr/lib/python3.10/asyncio/base_events.py", line 863, in getaddrinfo
    return await self.run_in_executor(
  File "/usr/lib/python3.10/concurrent/futures/thread.py", line 58, in run
    result = self.fn(*self.args, **self.kwargs)
  File "/usr/lib/python3.10/socket.py", line 955, in getaddrinfo
    for res in _socket.getaddrinfo(host, port, family, type, proto, flags):
socket.gaierror: [Errno -3] Temporary failure in name resolution
